Workbook
Name \0: #REF!
Name \a: #REF!
Name \B: #REF!
Name \C: #REF!
Name \D: #REF!
Name \E: #REF!
Name \F: #REF!
Name \G: #REF!
Name \H: #REF!
Name \I: #REF!
Name \J: #REF!
Name \K: #REF!
Name \L: #REF!
Name \M: #REF!
Name \N: #REF!
Name \O: #REF!
Name \P: #REF!
Name \Q: #REF!
Name \R: #REF!
Name \S: #REF!
Name \T: #REF!
Name \U: #REF!
Name \v: #REF!
Name \W: #REF!
Name \X: #REF!
Name \Y: #REF!
Name \Z: #REF!
Name _: {1,2,3,4;5,6,7,8;9,10,11,12;13,14,15,16}
Name _________________________________________________________________Hp3: {1,2,3,4;5,6,7,8;9,10,11,12;13,14,15,16}
Name _______________________________________________________________Hp3: {1,2,3,4;5,6,7,8;9,10,11,12;13,14,15,16}
Name _______________________________________________Hp3: {1,2,3,4;5,6,7,8;9,10,11,12;13,14,15,16}
Name _______________________________________________Hp3_1: {1,2,3,4;5,6,7,8;9,10,11,12;13,14,15,16}
Name ______________________________________________Hp3: {1,2,3,4;5,6,7,8;9,10,11,12;13,14,15,16}
Name _____________________________________________Hp3: {1,2,3,4;5,6,7,8;9,10,11,12;13,14,15,16}
Name ___________________________________________Hp3: {1,2,3,4;5,6,7,8;9,10,11,12;13,14,15,16}
Name __________________________________________Hp3: {1,2,3,4;5,6,7,8;9,10,11,12;13,14,15,16}
Name ________________________________________Hp3: {1,2,3,4;5,6,7,8;9,10,11,12;13,14,15,16}
Name _____________________________________Hp3: {1,2,3,4;5,6,7,8;9,10,11,12;13,14,15,16}
Name ____________________________________Hp3: {1,2,3,4;5,6,7,8;9,10,11,12;13,14,15,16}
Name ____________________________________Hp3_1: {1,2,3,4;5,6,7,8;9,10,11,12;13,14,15,16}
Name ___________________________________Hp3: {1,2,3,4;5,6,7,8;9,10,11,12;13,14,15,16}
Name _________________PAG2: #REF!
Name _________________PAG3: #REF!
Name _________________PAG7: #REF!
Name ________________PAG2: #REF!
Name ________________PAG3: #REF!
Name ________________PAG7: #REF!
Name _______________cla2: #REF!
Name _______________PAG2: #REF!
Name _______________PAG3: #REF!
Name _______________PAG7: #REF!
Name ______________cla2: #REF!
Name ______________PAG2: #REF!
Name ______________PAG3: #REF!
Name ______________PAG7: #REF!
Name _____________cla2: #REF!
Name _____________PAG2: #REF!
Name _____________PAG3: #REF!
Name _____________PAG7: #REF!
Name _____________R: #REF!

Sheet PORTADA
F1: VISADO CONTROL CRÉDITO
A3: INFORME DE TASACIÓN
F7: FECHA TASACIÓN:
F8: UF BASE:
F9: Valor USD
F10: Informe: | H10: Retasación
F11: Comuna
F12: Región
A14: CLIENTE: | G14: RUT:
A15: PROPIETARIO: | G15: RUT:
A17: Nº | B17: Nombre de la Propiedad | F17: Rol Avalúo | G17: Comuna | H17: Superf. Legal (ha) | I17: Superf. Real (ha)
A18: 1 | B18: =LEGAL!B6 | F18: =LEGAL!G6 | G18: =PORTADA!H11 | H18: =LEGAL!H6 | I18: =LEGAL!I6
A19: 2
A20: 3
F21: Total (ha) | H21: =SUM(H18:H20) | I21: =SUM(I18:I20)
A23: RESUMEN DE VALORES | D23: USD | F23: $ | H23: UF
A24: Suelos | D24: =F24/USD | F24: ='RESUMEN VALOR'!C6 | H24: =F24/UF
A25: Derechos de Agua | D25: =F25/USD | F25: ='AGUA '!J27 | H25: =F25/UF
A26: Infraestructura Hipotecable | D26: =F26/USD | F26: =CONSTR!S11 | H26: =F26/UF
A27: Infraestructura Prendable | D27: =F27/USD | F27: =CONSTR!S18 | H27: =F27/UF
A28: Plantaciones sin royalty | D28: =F28/USD | F28: =PLANTACION!H11 | H28: =F28/UF
A29: Plantaciones con royalty | D29: =F29/USD | F29: =PLANTACION!H17 | H29: =F29/UF
A30: Instalaciones - Equipos | D30: =F30/USD | F30: =CONSTR!S23 | H30: =F30/UF
A31: Valor Comercial | D31: =F31/USD | F31: =SUM(F24:G30) | H31: =F31/UF
A32: Valor comercial/ha | D32: =D31/$H$21 | F32: =F31/$H$21 | H32: =H31/$H$21
A33: Valor Liquidación | D33: ='RESUMEN VALOR'!E20 | F33: ='RESUMEN VALOR'!E19 | H33: ='RESUMEN VALOR'!E21
A36: OBSERVACIONES Y ADVERTENCIAS

Sheet LEGAL
A1: 2.-ANTECEDENTES LEGALES
A3: 2.1. ANTECEDENTES DEL DOMINIO E HIPOTECAS
A4: nº | B4: PROPIEDADES | C4: Inscripción dominio | F4: C.B.R. | G4: Rol SII | H4: Superficie Legal/SII (ha) | I4: Medición Satelital (ha) | J4: Hipoteca Rabofinance | K4: Tasación anterior | L4: Deuda de Contribuciones
C5: fs | D5: nº | E5: año
A6: 1 | I6: =H6
A7: =+A6+1
A8: 3
A9: 4
A10: 5
A11: 6
G12: TOTAL | H12: =SUM(H6:H11) | I12: =SUM(I6:I11) | L12: =SUM(L6:L11)
A14: OBSERVACIONES
A21: 2.2. ANTECEDENTES EXPROPIATORIOS:
A22: nº | B22: PROPIEDADES | C22: Afecto a Expropiación | E22: Superficie expropiada | G22: Franja y vía afecta a expropiación
A24: 1
A25: =+A24+1
A26: =+A25+1
A27: =+A26+1
A28: =+A27+1
A33: 2.3. DESLINDES LEGALES
A34: nº | B34: PROPIEDADES | C34: DESLINDES LEGALES
A35: =A6 | B35: =+B6
A36: =A7
A38: CERTIFICADO DE AVALÚO DEL SII Y CERTIFICADO DE DEUDA TGR

Sheet SUELOS  
A1: 3.- SUELOS
A33: 3.1.Descripción General Suelos
G34: Tipo propiedad: | H34: AGRÍCOLA
G35: Coordenada E
G36: Coordenada S
G37: Ciudad + cercana:
G38: Distancia
G39: Ruta de acceso
G40: Tipo de vía
A43: 3.2. VALOR SUELOS
A44: Propiedad | B44: Rol | C44: Clase | D44: Grado de | E44: Superficie | F44: Valor Unitario | G44: TOTAL
B45: SII | C45: Uso | D45: Habilitación | E45: m2 | F45: UF/m2 | G45: $ | H45: USD
G46: =F46*E46*UF | H46: =G46/USD
G47: =F47*E47*UF | H47: =G47/USD
G48: =F48*E48 | H48: =G48/USD
G49: =F49*E49 | H49: =G49/USD
G50: =F50*E50 | H50: =G50/USD
G51: =F51*E51 | H51: =G51/USD
G52: =F52*E52 | H52: =G52/USD
G53: =F53*E53 | H53: =G53/USD
C54: m2 | E54: =SUM(E46:E53) | G54: =SUM(G46:G53) | H54: =SUM(H46:H53)
C55: ha | E55: =E54/10000
A57: 3.4. MOSAICO DE ROLES
A59: PERÍMETRO,CLASIFICACIÓN DE USO DE SUELOS Y UBICACIÓN DENTRO DEL PRC, SEGÚN CARTOGRAFÍA DE CIREN (visor.sitrural.cl)
B308: Rol SII | C308: Zona | E308: Superf. m2 | F308: Valor UF/m2 | G308: Total $
E314: =SUM(E309:E313) | G314: =SUM(G309:G313)
G315: =G314/USD
C317: TOTAL | E317: =+E54+E314 | F317: m2 | G317: =G54+G314
G318: =G317/USD

Sheet AGUA 
A1: 4.- DERECHOS DE AGUA
A4: 4.1. INSCRIPCIÓN DE DERECHOS DE AGUA
A5: N° | B5: FUENTE | C5: Rol | D5: Derechos* | E5: Tipo | F5: Inscrito en | G5: Hipotecados a Rabofinance | H5: Datos de Inscripción | K5: CBR
C6: Avalúo | D6: Cantidad | F6: CPA | H6: fojas | I6: nº | J6: año
A7: 1
A8: 2
A9: 3
A10: 5
A11: 4
A13: Observaciones:
A22: 4.2. VALOR DE DERECHOS DE AGUA
A23: N° | B23: Fuente | C23: ROL | D23: Derechos | E23: Tipo | F23: Derechos expresados en acción | G23: Caudal Nominal (L/s) | H23: Hipotecados a Rabofinance | I23: Valor Unitario $ | J23: Total
C24: Avalúo | D24: Cantidad | J24: $ | K24: USD
A25: 1 | J25: =G25*I25 | K25: =J25/USD
A26: 4
B27: Total Derechos de Agua | G27: =SUM(G25:G26) | H27: =SUM(H25:H26) | J27: =SUM(J25:J26) | K27: =SUM(K25:K26)
A31: SUFICIENCIA DE DERECHOS DE AGUA
A36: INFORMACIÓN GENERAL DE LOS DERECHOS DE AGUA, IMAGEN DE EMPLAZAMIENTO PUNTO DE CAPTACIÓN

Sheet CONSTR
A3: 5- DESCRIPCIÓN DE INFRAESTRUCTURA E INSTALACIONES | P3: USD | Q3: =USD | R3: UF | S3: =UF
A4: 5.1.- CONSTRUCCIONES HIPOTECABLES
A5: N° | B5: EDIFICACIONES | C5: Estado conservación | D5: Ubicación Rol | E5: Superficie m2 | F5: Estructura Vertical Principal | G5: Data Aprox. | H5: Estructura Techumbre | I5: Pavimentos | J5: Cubierta | K5: Revestimiento Vertical | L5: Bien asegurable Sí/NO | M5: Costo Reposición UF/m2 | N5: Vida Útil Total (años) | O5: Vida remanente (años) | P5: Valor residual estimado % | Q5: Valor Unitario depreciado UF/m2 | R5: Valor Unitario $/m2 | S5: Valor Total Actual $
A6: 1
A7: 2
A8: 3
A9: 4
A10: 5
B11: Superficie Total | E11: =SUM(E6:E10) | S11: =SUM(S6:S10)
S12: =S11/$Q$3
A13: 5.2.- CONSTRUCCIONES PRENDABLES
A14: N° | B14: EDIFICACIONES | C14: Estado conservación | D14: Ubicación Rol | E14: Superficie m2 | F14: Estructura Vertical Principal | G14: Data Aprox. | H14: Estructura Techumbre | I14: Pavimentos | J14: Cubierta | K14: Revestimiento Vertical | L14: Bien asegurable Sí/NO | M14: Costo Reposición UF/m2 | N14: Vida Útil Total (años) | O14: Vida remanente (años) | P14: Valor residual estimado % | Q14: Valor Unitario depreciado UF/m2 | R14: Valor Unitario $/m2 | S14: Valor Total Actual $
A15: 1
A16: 2
B18: Superficie Total | E18: =SUM(E15:E17) | S18: =SUM(S15:S17)
S19: =S18/$Q$3
A20: 5.3.- INSTALACIONES Y OBRAS COMPLEMENTARIAS
A21: N° | B21: ÍTEM | C21: Estado conservación | D21: Ubicación Rol | E21: Cantidad | F21: Unidad | G21: Data Aprox. | H21: Descripción General | L21: Bien asegurable Sí/NO | M21: Costo Reposición Unitario UF | N21: Vida Útil Total (años) | O21: Vida remanente (años) | P21: Valor residual estimado | Q21: Valor Unitario depreciado | R21: Valor Unitario $ | S21: Valor Total Actual $
A22: 1 | O22: =IFERROR(IF((G22+N22-YEAR(PORTADA!$H$7))<0,0,G22+N22-YEAR(PORTADA!$H$7)),"") | Q22: =M22*(P22+(1-P22)*O22/N22) | R22: =Q22*$S$3 | S22: =R22*E22 | U22: =Q22/M22
B23: Superficie Total | E23: =SUM(E22:E22) | S23: =SUM(S22:S22)
S24: =S23/$Q$3
A26: OBSERVACIONES :
A35: 5.4. EMPLAZAMIENTO DE LAS EDIFICACIONES

Sheet PLANTACION
A1: 6.- PLANTACIONES
A3: 6.1. PLANTACIONES SIN ROYALTIES
A4: ESPECIE | B4: VARIEDAD | C4: AÑO | D4: Densidad plantas/ha | E4: ROL | F4: Superficie ha | G4: VALOR UNITARIO $/ha | H4: TOTAL $ | I4: TOTAL UF | J4: TOTAL USD | K4: Estado Plantación
G5: =PLANT!AA37 | H5: =F5*G5 | I5: =H5/UF | J5: =H5/USD
G6: =PLANT!AA38 | H6: =F6*G6 | I6: =H6/UF | J6: =H6/USD
G7: =PLANT!AA39 | H7: =F7*G7 | I7: =H7/UF | J7: =H7/USD
G8: =PLANT!AA40 | H8: =F8*G8 | I8: =H8/UF | J8: =H8/USD
G9: =PLANT!AA41 | H9: =F9*G9 | I9: =H9/UF | J9: =H9/USD
G10: =PLANT!AA42 | H10: =F10*G10 | I10: =H10/UF | J10: =H10/USD
D11: TOTALES | F11: =SUM(F5:F10) | H11: =SUM(H5:H10) | I11: =SUBTOTAL(9,I5:I10) | J11: =SUBTOTAL(9,J5:J10)
A13: 6.2. PLANTACIONES CON ROYALTIES
A14: ESPECIE | B14: VARIEDAD | C14: AÑO | D14: MARCO DE PLANTACIÓN | E14: ROL | F14: Superficie ha | G14: VALOR UNITARIO $/ha | H14: TOTAL $ | I14: TOTAL UF | J14: TOTAL USD | K14: Estado Plantación
F17: =SUM(F15:F16) | H17: =SUM(H15:H16) | I17: =SUM(I15:I16) | J17: =SUM(J15:J16)
A19: OBSERVACIONES
A24: DIFERENCIAS CON TASACIÓN ANTERIOR

Sheet RESUMEN VALOR
A1: RESUMEN DE VALORES
A4: =LEGAL!G6 | B4: =LEGAL!B6
A5: HIPOTECA | C5: VALOR COMERCIAL $ | D5: AJUSTE % | E5: VALOR LIQUIDACIÓN $
B6: SUELOS | C6: ='SUELOS '!G54 | D6: 0.7 | E6: =C6*D6
B7: DERECHOS DE AGUA | C7: ='AGUA '!J27 | D7: 0.7 | E7: =C7*D7
B8: DERECHOS DE AGUA SIN HIPOTECAR | D8: 0.7 | E8: =C8*D8
B9: INFRAESTRUCTURA HIPOTECABLE | C9: =SUMIF(CONSTR!$D$6:$D$10,'RESUMEN VALOR'!A4,CONSTR!$S$6:$S$10) | D9: 0.7 | E9: =C9*D9
B10: Total Hipoteca | C10: =SUM(C6:C9) | E10: =SUM(E6:E9)
A12: PRENDA | C12: VALOR COMERCIAL $ | D12: AJUSTE % | E12: VALOR LIQUIDACIÓN $
B13: PLANTACIONES | C13: =PLANTACION!H11 | D13: 0.5 | E13: =C13*D13
B14: PLANTACIONES CON ROYALTY | C14: =SUMIF(PLANTACION!$E$15:$E$16,'RESUMEN VALOR'!A4,PLANTACION!$H$15:$H$16) | D14: 0.5 | E14: =C14*D14
B15: INFRAESTRUCTURA PRENDABLE | C15: =SUMIF(CONSTR!$D$15:$D$17,'RESUMEN VALOR'!A4,CONSTR!$S$15:$S$17) | D15: 0.5 | E15: =C15*D15
B16: EQUIPOS E INSTALACIONES | C16: =SUMIF(CONSTR!$D$22:$D$22,'RESUMEN VALOR'!A4,CONSTR!$S$22:$S$22) | D16: 0.5 | E16: =C16*D16
B17: Total Prenda | C17: =SUM(C13:C16) | E17: =SUM(E13:E16)
B19: TOTAL | C19: =C17+C10 | E19: =E17+E10
B20: USD | C20: =C19/USD | E20: =E19/USD
B21: UF | C21: =C19/UF | E21: =E19/UF
A24: NOMBRE TASADOR | D24: FECHA | E24: =PORTADA!H7
A25: RUT | D25: DÓLAR | E25: =USD
A26: Empresa | C26: FIRMA | D26: UF | E26: =UF

Sheet Fotografias 1
B1: FOTOGRAFÍAS

Sheet REF. PROPIEDADES 
A2: REFERENCIAS DE MERCADO | G2: UF: | H2: =PORTADA!$H$8 | K2: USD | L2: =PORTADA!$H$9
A5: Ubicación | B5: Región | C5: Comuna | D5: Superficie (m2) | E5: Valor Total Publicado M$ | F5: Valor Total Publicado UF | G5: Fecha | H5: Tipo de Referencia | I5: Valor Total Ajustado UF | J5: Superf. edificada m2 | K5: Valor edificado UF/m2 | L5: Valor Depurado UF | M5: Valor Depurado UF/m2 | N5: Link oferta o datos compraventa (fs/nº/año/CBR) | O5: Breve descripción | P5: Referencia
A6: Ruta 5 Norte km 109 | B6: V | C6: Hijuelas | D6: 33000 | E6: =F6*H2/1000 | F6: 70000 | G6: 44225 | H6: Oferta | L6: =IF(H6="Oferta",F6*$F$229-(J6*K6),F6) | M6: =L6/D6 | N6: https://www.toctoc.com/propiedades/compracorredorasr/terreno/hijuelas/ruta-5-norte-hijuelas/1139997?utm_source=Lifull-connect&utm_medium=referrer | O6: Terreno plano, sin construcciones en enlace sur a Hijuelas.
A7: Ruta 5 norte | B7: V | C7: Hijuelas | D7: 10000 | E7: 270000 | F7: =E7*1000/H2 | G7: 44221 | H7: Oferta | L7: =IF(H7="Oferta",F7*$F$229-(J7*K7),F7) | M7: =L7/D7 | N7: http://www.ewilde.cl/propiedad/terreno-industrial-hijuelas/105 | O7: Poniente de ruta 5 norte, acceso por caletera.
A8: Chonchi | B8: X | C8: Chonchi | D8: 10000 | E8: 220000 | F8: =E8*1000/$H$2 | G8: 44856 | H8: Oferta | L8: =IF(H8="Oferta",F8*$F$229-(J8*K8),F8) | M8: =L8/D8 | N8: http://www.economicos.cl/propiedades/vendo-propiedad-industrial-en-chonchi-codAATIN6Q.html | O8: Propiedad industrial, con 300 m2 construidos con instalaciones relacionadas al rubro
A9: Castro | B9: X | C9: Castro | D9: 6890 | E9: 220000 | F9: =E9*1000/$H$2 | G9: 44877 | H9: Oferta | L9: =IF(H9="Oferta",F9*$F$229-(J9*K9),F9) | M9: =L9/D9 | N9: http://www.economicos.cl/propiedades/propiedad-industrial-en-venta-en-castro-codR76244956-0L0-21546.html | O9: Sector industrial entrada de Castro, acceso directo desde Ruta 5, cuenta con APR y con factibilidad de tendido trifásico.
A10: Calbuco | B10: X | C10: Calbuco | D10: 1300 | E10: 880000 | F10: 25000 | G10: 44958 | H10: Oferta | I10: =IF(H10="Oferta",F10*$F$229,F10) | J10: 1300 | K10: 15 | L10: =I10-J10*K10 | M10: =L10/D10 | N10: https://www.economicos.cl/propiedades/planta-procesadora-de-pescados-y-mariscos-codAATQBUI.html | O10: planta procesadora de pescado y marisco | P10: Ref ind 2025-171101
A11: Terreno en Tomé | B11: VIII | C11: Tomé | D11: 52924 | E11: =F11*$H$2/1000 | F11: 35000 | G11: 46143 | H11: Oferta | I11: =IF(H11="Oferta",F11*$F$229,F11) | J11: 0 | K11: 0 | L11: =I11-J11*K11 | M11: =L11/D11 | N11: https://www.portalinmobiliario.com/MLC-4112426366-remate-tome-terreno-calle-1-n493-lt-f-aysen-493-lt-g-_JM#polycard_client=search-desktop&be_origin=backend&search_layout=grid&position=10&type=item&tracking_id=627efe66-4b1a-4725-a564-d2472dfe928b&price_drop=true&sid=search | O11: se emplaza en la parte alta del cerro al norte de playa El Morro, cerca del acceso a Villa Cocholgüe, sin habilitar. | P11: Ref ind 2026-010701
A12: Terreno en Tomé | B12: VIII | C12: Tomé | D12: 5046 | E12: =F12*$H$2/1000 | F12: 19679 | G12: 45474 | H12: Oferta | I12: =IF(H12="Oferta",F12*$F$229,F12) | J12: 0 | K12: 0 | L12: =I12-J12*K12 | M12: =L12/D12 | N12: https://www.portalinmobiliario.com/MLC-1709335365-venta-de-terreno-en-tome-id-51987-lin-_JM#polycard_client=search-desktop&be_origin=backend&search_layout=grid&position=8&type=item&tracking_id=627efe66-4b1a-4725-a564-d2472dfe928b&price_drop=not_apply&sid=search | O12: Usos permitidos: Residencial y Equipamiento. Coeficiente ocupación de suelo: 40%. Coeficiente Constructibilidad 0,8. Densidad bruta: 100 hab/ha. Sup. Radial mínima: 500 | P12: Ref ind 2026-010702
A13: Propiedad en Ruta H-233, cercano a predio tasado | B13: VI | C13: Rancagua | D13: 140000 | E13: =F13*$H$2/1000 | F13: 91000 | G13: 46067 | H13: Oferta | I13: =IF(H13="Oferta",F13*$F$229,F13) | J13: 0 | K13: 0 | L13: =I13-J13*K13 | M13: =L13/D13 | N13: https://www.portalinmobiliario.com/MLC-3575446050-terreno-construccion-en-venta-en-rancagua-_JM#polycard_client=search-map&price_drop=not_apply&be_origin=backend&overlay_label=not_apply&search_layout=map&position=3&type=item&tracking_id=e2c67754-051a-4587-9a99-a09429be5d83&sid=search | O13: sector La Cruz, terreno ZEUES con posibildad de venta de lote de menor tamaño, mismo sector tasado
A14: Propiedad en Ruta H-233, cercano a predio tasado | B14: VI | C14: Rancagua | D14: 9800 | E14: =F14*$H$2/1000 | F14: 6370 | G14: 46067 | H14: Oferta | I14: =IF(H14="Oferta",F14*$F$229,F14) | J14: 0 | K14: 0 | L14: =I14-J14*K14 | M14: =L14/D14 | N14: https://www.portalinmobiliario.com/MLC-3575393050-terreno-construccion-en-venta-en-rancagua-_JM#polycard_client=search-map&price_drop=not_apply&be_origin=backend&overlay_label=not_apply&search_layout=map&position=6&type=item&tracking_id=e2c67754-051a-4587-9a99-a09429be5d83&sid=search | O14: sector La Cruz, terreno ZEUES con servicios básicos , mismo sector tasado
A15: Terreno plano, con proyecto inmobiliario en Ruta H-200 | B15: VI | C15: Rancagua | D15: 139400 | E15: =F15*$H$2/1000 | F15: 209100 | G15: 46067 | H15: Oferta | I15: =IF(H15="Oferta",F15*$F$229,F15) | J15: 0 | K15: 0 | L15: =I15-J15*K15 | M15: =L15/D15 | N15: https://www.portalinmobiliario.com/MLC-3336689894-terreno-san-ramon-proyecto-inmobiliario-_JM#polycard_client=search-map&price_drop=not_apply&be_origin=backend&overlay_label=not_apply&search_layout=map&position=5&type=item&tracking_id=3f11ce2a-e7f6-4a3c-8c8f-85900534085d&sid=search | O15: cercano a centro de la ciudad, uso mixto, zona en crecimiento
A16: Propiedad en zona ZEUES y AR-1, Ruta H-201 | B16: VI | C16: Rancagua | D16: =41.1*10000 | E16: =F16*$H$2/1000 | F16: 61000 | G16: 46217 | H16: Oferta | I16: =IF(H16="Oferta",F16*$F$229,F16) | J16: 0 | K16: 0 | L16: =I16-J16*K16 | M16: =L16/D16 | N16: https://www.portalinmobiliario.com/MLC-4188275772-oportunidad-de-inversion-en-terreno-amplio-170406-_JM#polycard_client=search-map&price_drop=not_apply&be_origin=backend&overlay_label=not_apply&search_layout=map&position=34&type=item&tracking_id=3f11ce2a-e7f6-4a3c-8c8f-85900534085d&sid=search | O16: terreno de 41,1 ha ubicado sector El Crucero, en zona ZEUES y AR1, similar al predio tasado, con acciones de canal, con construciones
A17: Predio de uso agrícola | B17: VI | C17: Rancagua | D17: =19.61*10000 | E17: 980500 | F17: 24032.705 | G17: 46036 | H17: Oferta | I17: =IF(H17="Oferta",F17*$F$229,F17) | J17: 0 | K17: 0 | L17: =I17-J17*K17 | M17: =L17/D17 | N17: https://www.portalinmobiliario.com/MLC-3505579952-agricola-en-venta-en-rancagua-_JM#polycard_client=recommendations_classi-realestate-vip&reco_backend=realestate-odin&reco_model=organicos-vis&reco_client=classi-realestate-vip&reco_item_pos=0&reco_backend_type=function&reco_id=16ac6830-2d5f-4850-9cf4-19133cc67fa7&sid=recos | O17: Propiedad agrícola, suelos planos, con derechos de agua
A18: Parcela cercana a predio tasado, Ruta H-15-G | B18: VI | C18: Rancagua | D18: 5000 | E18: 220000 | F18: 5392.3459 | G18: 46247 | H18: Oferta | I18: =IF(H18="Oferta",F18*$F$229,F18) | J18: 0 | K18: 0 | L18: =I18-J18*K18 | M18: =L18/D18 | N18: https://www.portalinmobiliario.com/MLC-4342889654-amplitud-y-naturaleza-en-un-lugar-unico-179096-_JM#polycard_client=search-map&price_drop=not_apply&be_origin=backend&overlay_label=not_apply&search_layout=map&position=6&type=item&tracking_id=f23461ee-dc1e-411b-9386-30d421f3ff14&sid=search | O18: terreno plano, mismo sector tasado
A19: Propiedad agrícola Coltauco | B19: VI | C19: Rancagua | D19: 35800 | E19: 275390.35 | F19: 6750 | G19: 46247 | H19: Oferta | I19: =IF(H19="Oferta",F19*$F$229,F19) | J19: 0 | K19: 0 | L19: =I19-J19*K19 | M19: =L19/D19 | N19: https://www.engelvoelkers.com/cl/es/exposes/c25f1ad3-44a1-5c0a-a91c-8ec1906bda6f | O19: terreno plano, plantado con alfalfa, acceso por ruta H 30
A20: Propiedad cercana a estadio Marista | B20: VI | C20: Rancagua | D20: 22000 | E20: 334548.27 | F20: 8200 | G20: 46247 | H20: Oferta | I20: =IF(H20="Oferta",F20*$F$229,F20) | J20: 0 | K20: 0 | L20: =I20-J20*K20 | M20: =L20/D20 | N20: https://www.engelvoelkers.com/cl/es/exposes/ae8247fc-3566-59b0-98da-70cbb564e3b6 | O20: terreno plano, cercano al sector tasado, sin plantaciones, con derechos de agua
A21: Terreno en Tomé | B21: VIII | C21: Tomé | D21: 45000 | E21: =F21*$H$2/1000 | F21: 202500 | G21: 46174 | H21: Oferta | I21: =IF(H21="Oferta",F21*$F$229,F21) | J21: 0 | K21: 0 | L21: =I21-J21*K21 | M21: =L21/D21 | N21: https://www.toctoc.com/propiedades/compracorredorasr/terreno/tome/gran-lote-gran-vista-al-mar-en-tome/3ab54e9c4b51c5cbaa15536968469c4901c302a6?utm_source=venta%2Fterreno%2Ftome | O21: Lote colindante con la propiedad, sector oriente, sin habilitar, con vegetación y pendiente | P21: Ref ind 2026-090701
A22: Terreno en Tomé | B22: VIII | C22: Tomé | D22: 4445 | E22: =F22*$H$2/1000 | F22: 16000 | G22: 45474 | H22: Oferta | I22: =IF(H22="Oferta",F22*$F$229,F22) | J22: 0 | K22: 0 | L22: =I22-J22*K22 | M22: =L22/D22 | N22: https://www.portalinmobiliario.com/MLC-1709451087-venta-de-terreno-en-tome-id-51986-lin-_JM#polycard_client=search-desktop&be_origin=backend&search_layout=grid&position=7&type=item&tracking_id=627efe66-4b1a-4725-a564-d2472dfe928b&price_drop=not_apply&sid=search | O22: Usos permitidos: Residencial y Equipamiento. Coeficiente ocupación de suelo: 40%. Coeficiente Constructibilidad 0,8. Densidad bruta: 100 hab/ha. Sup. Radial mínima: 500 | P22: Ref ind 2026-010703
A23: Terreno en Tomé | B23: VIII | C23: Tomé | D23: 107772 | E23: =F23*$H$2/1000 | F23: 27500 | G23: 45870 | H23: Oferta | I23: =IF(H23="Oferta",F23*$F$229,F23) | J23: 0 | K23: 0 | L23: =I23-J23*K23 | M23: =L23/D23 | N23: https://www.portalinmobiliario.com/MLC-2950222766-venta-de-terreno-urbano-en-tome-id-77323-lin-_JM#polycard_client=search-desktop&be_origin=backend&search_layout=grid&position=5&type=item&tracking_id=627efe66-4b1a-4725-a564-d2472dfe928b&price_drop=not_apply&sid=search | O23: Terreno urbano ubicado en la comuna de Tomé, ideal para el desarrollo de proyectos habitacionales | P23: Ref ind 2026-010704
A24: Terreno en Tomé | B24: VIII | C24: Tomé | D24: 661 | E24: 119000 | F24: =E24*1000/$H$2 | G24: 45108 | H24: Oferta | I24: =IF(H24="Oferta",F24*$F$229,F24) | J24: 0 | K24: 0 | L24: =I24-J24*K24 | M24: =L24/D24 | N24: https://www.portalinmobiliario.com/MLC-3221771482-venta-de-terreno-san-jose-del-mar-_JM#polycard_client=search-desktop&be_origin=backend&search_layout=grid&position=9&type=item&tracking_id=627efe66-4b1a-4725-a564-d2472dfe928b&price_drop=not_apply&sid=search | O24: terreno en zona urbana, semiplano, sin habilitar | P24: Ref ind 2026-010705
A25: Terreno urbano | B25: VIII | C25: Tomé | D25: 82000 | E25: =F25*$H$2/1000 | F25: 98400 | G25: 45246 | H25: Oferta | I25: =IF(H25="Oferta",F25*$F$229,F25) | J25: 0 | K25: 0 | L25: =I25-J25*K25 | M25: =L25/D25 | N25: https://www.economicos.cl/propiedades/vendo-terreno-para-inversion-en-tome-codAAUDGTQ.html | O25: 82.000 m2 de terreno urbano, en el camio entre Tomé y Coliumo, a orilllas de carretera principal | P25: Ref ind 2026-010706
A26: Terreno urbano | B26: VIII | C26: Tomé | D26: 4255 | E26: =F26*$H$2/1000 | F26: 9600 | G26: 46165 | H26: Oferta | I26: =IF(H26="Oferta",F26*$F$229,F26) | J26: 0 | K26: 0 | L26: =I26-J26*K26 | M26: =L26/D26 | N26: https://inmueble.mercadolibre.cl/MLC-4012877246-venta-terreno-sitio-4255mts-tome-_JM#polycard_client=search-desktop&be_origin=backend&search_layout=grid&position=28&type=item&tracking_id=ba0217bd-06eb-4bc1-b47c-3b53218b6b14&price_drop=not_apply&sid=search | O26: Terreno plano, sin construcciones, sector urbano, calle Los Cerezos | P26: Ref ind 2026-010707
A27: Terreno urbano | B27: VIII | C27: Tomé | D27: 19390 | E27: =F27*$H$2/1000 | F27: =2*D27 | G27: 46054 | H27: Oferta | I27: =IF(H27="Oferta",F27*$F$229,F27) | J27: 0 | K27: 0 | L27: =I27-J27*K27 | M27: =L27/D27 | N27: https://inmueble.mercadolibre.cl/MLC-1834433249-venta-de-terreno-en-tome-id-82655-lin-_JM#polycard_client=search-desktop&be_origin=backend&search_layout=grid&position=4&type=item&tracking_id=77beb2c4-3168-46f3-9b70-b4cdafabb769&price_drop=not_apply&sid=search | O27: Coef. Constructibilidad: 4.4 Coef. Ocupación de Suelo: 0.2 Densidad: Libre Sup. Predial Mínima: 2.500 m² Altura Máxima: 7 m | P27: Ref ind 2026-010708
A28: Terreno urbano | B28: VIII | C28: Tomé | D28: 125900 | E28: =F28*$H$2/1000 | F28: 88130 | G28: 46196 | H28: Oferta | I28: =IF(H28="Oferta",F28*$F$229,F28) | J28: 0 | K28: 0 | L28: =I28-J28*K28 | M28: =L28/D28 | N28: https://www.portalinmobiliario.com/MLC-4105687354-terreno-para-desarrollo-inmobiliario-_JM#polycard_client=search-desktop&be_origin=backend&search_layout=grid&position=11&type=item&tracking_id=627efe66-4b1a-4725-a564-d2472dfe928b&price_drop=not_apply&sid=search | O28: lomaje suave en el interior costero entre tomé y Dichato, 8 ha de zona residencial mixta para subdividir en hasta 300 mt2 | P28: Ref ind 2026-010709
A29: Terreno urbano | B29: VIII | C29: Tomé | D29: 4200 | E29: =F29*$H$2/1000 | F29: 12637 | G29: 45901 | H29: Oferta | I29: =IF(H29="Oferta",F29*$F$229,F29) | J29: 0 | K29: 0 | L29: =I29-J29*K29 | M29: =L29/D29 | N29: https://inmueble.mercadolibre.cl/MLC-3106130606-venta-de-terreno-en-tome-id-77016-lin-_JM#polycard_client=search-desktop&be_origin=backend&search_layout=grid&position=7&type=item&tracking_id=77beb2c4-3168-46f3-9b70-b4cdafabb769&price_drop=not_apply&sid=search | O29: terreno urbano, calle Los Nogales 1196, Tome | P29: Ref ind 2026-010710
A30: Castro, terreno industrial Ruta 5 Sur | B30: X | C30: Castro | D30: 5000 | E30: =F30*H2/1000 | F30: 9800 | G30: 45978 | H30: Oferta | I30: =IF(H30="Oferta",F30*$F$229,F30) | J30: 0 | L30: =I30-J30*K30 | M30: =L30/D30 | N30: https://inmobisur.cl/propiedad/detalle/terreno-industrial-para-venta-1615 | O30: Terreno plano, sin construcciones, sector uso industrial | P30: Ref ind 2025-171102
A31: Parcela sector Huitauque | B31: X | C31: Chonchi | D31: 7271 | E31: 86000 | F31: =E31*1000/H2 | G31: 45978 | H31: Oferta | J31: 0 | L31: =IF(H31="Oferta",F31*$F$229-(J31*K31),F31) | M31: =L31/D31 | N31: https://cl.portalterreno.com/propiedad/venta/parcela/chonchi/293828-excelente-parcela-vistas-al-mar-quinched-chiloe | O31: terreno cercano al mar, sin habilitar | P31: Ref ind 2025-171103
A32: Terreno con playa en Chonchi | B32: X | C32: Chonchi | D32: 16100 | E32: =F32*H2/1000 | F32: 9660 | G32: 45978 | H32: Oferta | I32: =IF(H32="Oferta",F32*$F$229,F32) | J32: 0 | L32: =I32-J32*K32 | M32: =L32/D32 | N32: https://calvacindustrial.cl/propiedad/se-vende-espectacular-terreno-161ha-en-chonchi-con-acceso-a-la-playa/ | O32: terreno con acceso a playa, cercano a Chonchi, sin habilitar, sin construcciones | P32: Ref ind 2025-171104
A33: Terreno cercano a Ruta 5 | B33: X | C33: Chonchi | D33: 20700 | E33: 230000 | F33: 5802 | G33: 45978 | H33: Oferta | I33: =IF(H33="Oferta",F33*$F$229,F33) | J33: 0 | L33: =I33-J33*K33 | M33: =L33/D33 | N33: https://cl.portalterreno.com/propiedad/venta/sitio/chonchi/346206-ruta-5-sur-a-38-km-de-la-ciudad-de-castro | O33: terreno con acceso directo al río, sector Llau Llao, sin habilitar | P33: Ref ind 2025-171105
A34: Terreno en Quemchi | B34: X | C34: Quemchi | D34: 5100 | E34: 41943 | F34: 1058 | G34: 45474 | H34: Oferta | J34: 0 | L34: =IF(H34="Oferta",F34*$F$229-(J34*K34),F34) | M34: =L34/D34 | N34: https://www.toctoc.com/propiedades/compracorredorasr/terreno/quemchi/sitio-en-venta-en-quemchi/5a5e157f36fffcbb5c464fba1addd2f2e5d2806e | O34: terreno cercano a playa, con acceso a servicios básicos | P34: Ref ind 2025-171106
A35: Terreno industrial Mocopulli | B35: X | C35: Dalcahue | D35: 5000 | E35: 376614 | F35: 9500 | G35: 45950 | H35: Oferta | I35: =IF(H35="Oferta",F35*$F$229,F35) | J35: 0 | L35: =I35-J35*K35 | M35: =L35/D35 | N35: https://www.toctoc.com/propiedades/compracorredorasr/terreno/dalcahue/sitio-industrial-en-venta-en-dalcahue/f329050c465e9face18c027da2bc68ef24a8a378 | O35: terrenos industriales en Mocopulli, cercano a aeropuerto y Ruta 5 Sur | P35: Ref ind 2025-171107
A36: Terreno industrial Puerto Montt | B36: X | C36: Puerto Montt | D36: 34190 | E36: =F36*H2/1000 | F36: 67250 | G36: 45979 | H36: Oferta | I36: =IF(H36="Oferta",F36*$F$229,F36) | J36: 0 | L36: =I36-J36*K36 | M36: =L36/D36 | N36: http://www.economicos.cl/propiedades/sitio-o-terreno-en-venta-en-puerto-montt-codR77087734-2L0-37065.html | O36: conformado por dos terrenos semiplanos, con construcciones | P36: Ref ind 2025-181101
A37: Terreno en Calbuco | B37: X | C37: Puerto Montt | D37: 12288 | E37: 450000 | F37: =E37*1000/$H$2 | G37: 45980 | H37: Oferta | I37: =IF(H37="Oferta",F37*$F$229,F37) | J37: 0 | L37: =I37-J37*K37 | M37: =L37/D37 | N37: https://www.coldwellbanker.cl/propiedad/detalle/terreno-ruta-5-puerto-montt-9531 | O37: terreno plano, sin habilitar, sector industrial y comercial, cercano a aeropuerto | P37: Ref ind 2025-191102
A38: Propiedad industrial en Calbuco | B38: X | C38: Puerto Montt | D38: 7000 | E38: 1500000 | F38: =E38*1000/$H$2 | G38: 45980 | H38: Oferta | I38: =IF(H38="Oferta",F38*$F$229,F38) | J38: 216 | K38: 15 | L38: =I38-J38*K38 | M38: =L38/D38 | N38: http://www.economicos.cl/propiedades/vendo-terreno-industrial-codAAU2M7Y.html | O38: terreno plano con dos galpones industriales | P38: Ref ind 2025-191103
A39: Propiedad industrial en Puerto Montt | B39: X | C39: Puerto Montt | D39: 10000 | E39: 2860347 | F39: =E39*1000/$H$2 | G39: 45980 | H39: Oferta | I39: =IF(H39="Oferta",F39*$F$229,F39) | J39: 2986 | K39: 15 | L39: =I39-J39*K39 | M39: =L39/D39 | N39: http://www.economicos.cl/propiedades/comercial-mares-de-chiloe-spa-puerto-montt-codAAUWBJA.html | O39: terreno en forma de rectángulo irregular, con un frente a la ruta, con construcciones de tipo industrial | P39: Ref ind 2025-191104
A40: Propiedad industrial en Cardonal | B40: X | C40: Puerto Montt | D40: 10600 | E40: 150000 | F40: =E40*1000/$H$2 | G40: 45771 | H40: Oferta | I40: =IF(H40="Oferta",F40*$F$229,F40) | J40: 0 | K40: 0 | L40: =I40-J40*K40 | M40: =L40/D40 | N40: http://www.economicos.cl/propiedades/oportunidad-dos-parcelas-parque-industrial-apiasmontt-codAAULS3Y.html | O40: dos parcelas, total de 10.600 m2, a 3 kilómetros de la Rotanda Cardonal, en Ruta 226 a Tepual. Existe conexión a electricidad y agua | P40: Ref ind 2025-191105
A41: Terreno en Puerto Montt | B41: X | C41: Puerto Montt | D41: 31625 | E41: =F41*$H$2/1000 | F41: 63000 | G41: 45980 | H41: Oferta | I41: =IF(H41="Oferta",F41*$F$229,F41) | J41: 0 | K41: 0 | L41: =I41-J41*K41 | M41: =L41/D41 | N41: http://www.economicos.cl/propiedades/sitio-o-terreno-en-venta-en-puerto-montt-codR77205366-5L0-5263V.html | O41: terreno de uso comercial e industrial, cin construcciones | P41: Ref ind 2025-191106
A42: Terreno en Puerto Montt | B42: X | C42: Puerto Montt | D42: 30000 | E42: =F42*$H$2/1000 | F42: 50000 | G42: 45980 | H42: Oferta | I42: =IF(H42="Oferta",F42*$F$229,F42) | J42: 0 | K42: 0 | L42: =I42-J42*K42 | M42: =L42/D42 | N42: http://www.economicos.cl/propiedades/sitio-o-terreno-en-venta-en-puerto-varas-codR77205366-5L0-27548V.html | O42: terreno plano, acceso por caletera Ruta 5 Sur, acceso a servicios básicos | P42: Ref ind 2025-191107
A43: Terreno con playa en Quemchi | B43: X | C43: Quemchi | D43: 52000 | E43: =F43*$H$2/1000 | F43: 20000 | G43: 45980 | H43: Oferta | I43: =IF(H43="Oferta",F43*$F$229,F43) | J43: 0 | K43: 0 | L43: =I43-J43*K43 | M43: =L43/D43 | N43: https://ppartnersgroup.com/es-cl/propiedad/lindo-terreno-con-orilla-de-playa-sector-arrayanes-de-huite-quemchi/66798b803bdb40e7c2d66b81/ | O43: terreno irregular, semiplano, sin habilitar con frente a borde costero | P43: Ref ind 2025-191108
...

Sheet REF. Canal 
A2: REFERENCIAS DE MERCADO DERECHOS DE AGUA | J2: UF: | K2: =PORTADA!$H$8
A5: Región | B5: Comuna | C5: Sub-Cuenca | D5: Fuente | E5: Nombre de la Fuente | F5: Derechos | G5: Tipo | H5: Q Nominal L/s | I5: Valor Total M$ | J5: Valor Unit. M$/(L/s) | K5: Valor UF/(L/s) | L5: Valor Unit. Ajustado M$/L/s | M5: Fecha / Año | N5: Tipo de Referencia | O5: Link oferta o datos compraventa (fs/nº/año/CBR)
A6: V | B6: Catemu | C6: Río Aconcagua | D6: Estero | E6: Catemu | F6: 20 | G6: L/s | H6: 20 | I6: =J6*H6 | J6: =7000 | K6: =J6*1000/$K$2 | L6: =IF(N6="Oferta",J6*$D$60,J6) | M6: 45642 | N6: Oferta | O6: https://gesaguas.cl/derecho/19
A7: V | B7: Rinconada | C7: 1a seccción Río Aconcagua | D7: Canal | E7: San Miguel | F7: 5 | G7: acción | H7: 8 | I7: 64000 | J7: 8000 | K7: =J7*1000/K2 | L7: =IF(N7="Oferta",J7*$D$60,J7) | M7: 45767 | N7: Oferta | O7: https://gesaguas.cl/derecho/184
A8: V | B8: LLay Llay | C8: Río Aconcagua | D8: Canal | E8: Ucuquer | F8: 0.5 | G8: acción | H8: =F8 | I8: 1000 | J8: =I8/F8 | K8: =J8*1000/$K$2 | L8: =IF(N8="Oferta",J8*$D$60,J8) | M8: 45309 | N8: Venta | O8: fojas 28v nº 28del año 2024 CBR Llay Llay
A9: V | B9: Hijuelas | C9: Río Aconcagua | D9: Canal | E9: Purehue | F9: 43 | G9: acción | H9: =260/159.25*F9 | I9: 215000 | J9: =I9/H9 | K9: =J9*1000/$K$2 | L9: =IF(N9="Oferta",J9*$D$60,J9) | M9: 45428 | N9: Venta | O9: fojas 111v nº 96 del año 2024CBR Llay Llay
A10: V | B10: Hijuelas | C10: Río Aconcagua | D10: Canal | E10: La Sombra | F10: 12 | G10: acción | H10: =1000/390.09*F10 | I10: 60000 | J10: =I10/H10 | K10: =J10*1000/$K$2 | L10: =IF(N10="Oferta",J10*$D$60,J10) | M10: 45428 | N10: Venta | O10: fojas 113 nº 97 del año 2024CBR Llay Llay
A11: V | B11: Hijuelas | C11: Río Aconcagua | D11: Canal | E11: Ocoa | F11: 0.3 | G11: acción | H11: =736/800*F11 | I11: 1000 | J11: =I11/H11 | K11: =J11*1000/$K$2 | L11: =IF(N11="Oferta",J11*$D$60,J11) | M11: 45530 | N11: Venta | O11: fojas 190 v nº 165 del año 2024 CBR Llay Llay
A12: V | B12: Llay Llay | C12: Río Aconcagua | D12: Canal | E12: Canal del Bajo | F12: 12.54 | G12: acción | H12: 53.5 | I12: 200000 | J12: =I12/H12 | K12: =J12*1000/$K$2 | L12: =IF(N12="Oferta",J12*$D$60,J12) | M12: 44701 | N12: Venta | O12: 147/140/2022/CBR Llay Llay
A13: V | B13: Catemu | C13: 2ª sección río Aconcagua | D13: Canal | E13: Comunero o Ucuquer | F13: 12 | G13: acción | H13: 12 | I13: 88320 | J13: =I13/H13 | K13: =J13*1000/$K$2 | L13: =IF(N13="Oferta",J13*$D$60,J13) | M13: 45642 | N13: Oferta | O13: https://www.aguacircular.cl/00618-054-05
A14: V | B14: Catemu | C14: 2ª sección río Aconcagua | D14: Canal | E14: Valdesano | F14: 300 | G14: acción | H14: 9.88 | I14: 73065 | J14: =I14/H14 | K14: =J14*1000/$K$2 | L14: =IF(N14="Oferta",J14*$D$60,J14) | M14: 45642 | N14: Oferta | O14: https://www.aguacircular.cl/00619-054-05
A15: V | B15: Catemu | C15: 2ª sección río Aconcagua | D15: Canal | E15: Las Vegas Molino | F15: 2.28 | G15: acción | H15: 15.64 | I15: 86024 | J15: =I15/H15 | K15: =J15*1000/$K$2 | L15: =IF(N15="Oferta",J15*$D$60,J15) | M15: 45642 | N15: Oferta | O15: https://www.aguacircular.cl/01116-054-05
A16: V | B16: San Esteban | C16: 1ª sección Río Aconcagua | D16: Canal | E16: San Miguel | F16: 5.706 | G16: acción | H16: 10.27 | I16: 82160 | J16: =I16/H16 | K16: =J16*1000/$K$2 | L16: =IF(N16="Oferta",J16*$D$60,J16) | M16: 45642 | N16: Oferta | O16: https://www.aguacircular.cl/00098-054-05
A17: V | B17: La Calera | C17: 3ª sección Río Aconcagua | D17: Canal | E17: Waddington | F17: 20 | G17: acción | H17: =F17 | I17: 117551 | J17: =I17/H17 | K17: =J17*1000/$K$2 | L17: =IF(N17="Oferta",J17*$D$60,J17) | M17: 45642 | N17: Oferta | O17: https://www.aguacircular.cl/00647-054-05
A18: V | B18: La Calera | C18: 3ª sección Río Aconcagua | D18: Canal | E18: Waddington | F18: 2.9 | G18: acción | H18: =F18 | I18: 28938 | J18: =I18/H18 | K18: =J18*1000/$K$2 | L18: =IF(N18="Oferta",J18*$D$60,J18) | M18: 45642 | N18: Oferta | O18: https://www.aguacircular.cl/00332-054-05
A19: V | B19: Quillota | C19: 3ª sección Río Aconcagua | D19: Canal | E19: Comunidad Quillota y Candelaria | F19: 9 | G19: acción | H19: =F19*2.57 | I19: 61851 | J19: =I19/H19 | K19: =J19*1000/$K$2 | L19: =IF(N19="Oferta",J19*$D$60,J19) | M19: 45642 | N19: Oferta | O19: https://www.aguacircular.cl/00633-054-05
A20: V | B20: Quillota | C20: Río Aconcagua | D20: Canal | E20: Candelaria | F20: 0.5046 | G20: acción | H20: 0.5046 | I20: 2000 | J20: 3963.5355 | K20: 122.48751 | L20: =IF(N20="Oferta",J20*$D$60,J20) | M20: 43881 | N20: Venta | O20: 57 / 49 / 2020/ CBR Quillota
A21: V | B21: Quillota | C21: Río Aconcagua | D21: Canal | E21: Tambor | F21: 0.5 | G21: acción | H21: 0.5 | I21: 1528.038 | J21: 3056.076 | K21: 108 | L21: =IF(N21="Oferta",J21*$D$60,J21) | M21: 43882 | N21: Venta | O21: 58 / 51 / 2020/ CBR Quillota
A22: V | B22: Los Andes | C22: 1ª sección Río Aconcagua | D22: Canal | E22: Rinconada | F22: 5.538 | G22: acción | H22: 9.9684 | I22: 69778.8 | J22: 7000 | K22: =J22*1000/$K$2 | L22: =IF(N22="Oferta",J22*$D$60,J22) | M22: 45370 | N22: Venta | O22: fojas 92v nº 109 del año 2024 CBR Los Andes
A23: V | B23: Los Andes | C23: 1ª sección Río Aconcagua | D23: Canal | E23: Rinconada | F23: 3.842 | G23: acción | H23: 6.9156 | I23: 48419.37 | J23: =I23/H23 | K23: =J23*1000/$K$2 | L23: =IF(N23="Oferta",J23*$D$60,J23) | M23: 45370 | N23: Venta | O23: fojas 93v nº 111 del año 2024 CBR Los Andes
A24: V | B24: Los Andes | C24: 1ª sección Río Aconcagua | D24: Canal | E24: Rinconada | F24: 5.517 | G24: acción | H24: 9.9306 | I24: 69521.7 | J24: =I24/H24 | K24: =J24*1000/$K$2 | L24: =IF(N24="Oferta",J24*$D$60,J24) | M24: 45370 | N24: Venta | O24: fojas 91 v nº 109 del año 2024 CBR Los Andes
A25: V | B25: Los Andes | C25: 1ª sección Río Aconcagua | D25: Canal | E25: San Miguel | F25: 5 | G25: acción | H25: 8 | I25: 64000 | J25: =I25/H25 | K25: =J25*1000/$K$2 | L25: =IF(N25="Oferta",J25*$D$60,J25) | M25: 45767 | N25: Oferta | O25: https://www.aguacircular.cl/01327-054-05
A26: V | B26: Los Andes | C26: 1ª sección Río Aconcagua | D26: Canal | E26: San Miguel | F26: 10.27 | G26: L/s | H26: 10.27 | I26: 82160 | J26: =I26/H26 | K26: =J26*1000/$K$2 | L26: =IF(N26="Oferta",J26*$D$60,J26) | M26: 45767 | N26: Oferta | O26: https://www.aguacircular.cl/00098-054-05
A27: V | B27: Catemu | C27: 2ª sección río Aconcagua | D27: Canal | E27: Comunero o Ucuquer | F27: 12 | G27: acción | H27: 12 | I27: 89817 | J27: =I27/H27 | K27: =J27*1000/$K$2 | L27: =IF(N27="Oferta",J27*$D$60,J27) | M27: 45767 | N27: Oferta | O27: https://www.aguacircular.cl/00618-054-05
A28: V | B28: Catemu | C28: 2ª sección río Aconcagua | D28: Canal | E28: Valdesano | F28: 300 | G28: acción | H28: 9.88 | I28: 74303 | J28: =I28/H28 | K28: =J28*1000/$K$2 | L28: =IF(N28="Oferta",J28*$D$60,J28) | M28: 45767 | N28: Oferta | O28: https://www.aguacircular.cl/00619-054-05
A29: V | B29: Los Andes | C29: Río Aconcagua | D29: Pozo | E29: sin nombre | F29: 1 | G29: L/s | H29: =+F29 | I29: 7000 | J29: =I29/H29 | K29: =J29*1000/$K$2 | L29: =IF(N29="Oferta",J29*$D$60,J29) | M29: 43717 | N29: Venta | O29: 174 / 230 / 2019 / Los Andes
A30: V | B30: Los Andes | C30: Río Aconcagua | D30: Canal | E30: Rinconada | F30: 0.25 | G30: acción | H30: 0.45 | I30: 1250 | J30: =I30/H30 | K30: =J30*1000/$K$2 | L30: =IF(N30="Oferta",J30*$D$60,J30) | M30: 43691 | N30: Venta | O30: 159 v / 210 / 2019/ Los Andes
A31: V | B31: Los Andes | C31: Río Aconcagua | D31: Canal | E31: Quilpué | F31: 0.267 | G31: acción | H31: =F31*1.8 | I31: 1000 | J31: =I31/H31 | K31: =J31*1000/$K$2 | L31: =IF(N31="Oferta",J31*$D$60,J31) | M31: 43651 | N31: Venta | O31: 128 v / 166 / 2019 / Los Andes
A32: V | B32: Los Andes | C32: Río Aconcagua | D32: Canal | E32: San Miguel | F32: 3.5 | G32: acción | H32: =F32*1.8 | I32: 32000 | J32: =I32/H32 | K32: =J32*1000/$K$2 | L32: =IF(N32="Oferta",J32*$D$60,J32) | M32: 43633 | N32: Venta | O32: 113 v / 148 / 2019 / Los Andes
A33: V | B33: Los Andes | C33: Río Aconcagua | D33: Canal | E33: San Rafael | F33: 0.655 | G33: acción | H33: =F33*1.8 | I33: 9650 | J33: =I33/H33 | K33: =J33*1000/$K$2 | L33: =IF(N33="Oferta",J33*$D$60,J33) | M33: 43612 | N33: Venta | O33: 108 / 140 / 2019 / Los Andes
A34: V | B34: Los Andes | C34: Estero Quilpué | D34: Canal | E34: El Monte | F34: 2.88 | G34: acción | H34: 2.88 | I34: 9741 | J34: =I34/H34 | K34: =J34*1000/$K$2 | L34: =IF(N34="Oferta",J34*$D$60,J34) | M34: 43553 | N34: Venta | O34: 58 / 66 / 2019 / Los Andes
A35: V | B35: Los Andes | C35: Río Aconcagua | D35: Canal | E35: Los Cantos | F35: 32 | G35: acción | H35: 40.92 | I35: 154674 | J35: =I35/H35 | K35: =J35*1000/$K$2 | L35: =IF(N35="Oferta",J35*$D$60,J35) | M35: 43480 | N35: Venta | O35: 10 / 13 / 2019 /Los Andes
A36: V | B36: Los Andes | C36: Río Aconcagua | D36: Canal | E36: Quilpué | F36: 1.424 | G36: acción | H36: 2.563 | I36: 10213 | J36: =I36/H36 | K36: =J36*1000/$K$2 | L36: =IF(N36="Oferta",J36*$D$60,J36) | M36: 43480 | N36: Venta | O36: 10 / 13 / 2019 /Los Andes
A37: V | B37: Chimbarongo | C37: Río Rapel | D37: Canal | E37: Común | F37: 12.04 | G37: L/s | H37: 12.04 | I37: 122513 | J37: =I37/H37 | K37: =J37*1000/$K$2 | L37: =IF(N37="Oferta",J37*$D$60,J37) | M37: 45792 | N37: Oferta | O37: https://www.aguacircular.cl/00277-060-06
A38: VI | B38: San Vicente TT | C38: Río Rapel | D38: Canal | E38: El Naranjal | F38: 108.5 | G38: L/s | H38: 108.5 | I38: =4000*108.5 | J38: =I38/H38 | K38: =J38*1000/$K$2 | L38: =IF(N38="Oferta",J38*$D$60,J38) | M38: 46157 | N38: Oferta | O38: https://www.gesaguas.cl/derecho/20
A39: VI | B39: Machalí | C39: Río Cachapoal | D39: Canal | E39: San Pedro, Población | F39: 196.56 | G39: L/s | H39: 196.56 | I39: 716924 | J39: =I39/H39 | K39: =J39*1000/$K$2 | L39: =IF(N39="Oferta",J39*$D$60,J39) | M39: 46157 | N39: Oferta | O39: https://www.aguacircular.cl/00540-060-06
A40: VI | B40: Machalí | C40: Río Cachapoal | D40: Canal | E40: San Pedro, Población | F40: 8.1 | G40: L/s | H40: 8.1 | I40: 35400 | J40: =I40/H40 | K40: =J40*1000/$K$2 | L40: =IF(N40="Oferta",J40*$D$60,J40) | M40: 46157 | N40: Oferta | O40: https://www.aguacircular.cl/01265-060-06
A41: VI | B41: Machalí | C41: Río Cachapoal | D41: Canal | E41: San Pedro, Población | F41: 3.85 | G41: L/s | H41: 3.85 | I41: 31230 | J41: =I41/H41 | K41: =J41*1000/$K$2 | L41: =IF(N41="Oferta",J41*$D$60,J41) | M41: 45792 | N41: Oferta | O41: https://www.aguacircular.cl/01119-060-06
A42: VI | B42: Machalí | C42: Río Cachapoal | D42: Canal | E42: San Pedro, Población | F42: 7.33 | G42: L/s | H42: 7.33 | I42: 25000 | J42: =I42/H42 | K42: =J42*1000/$K$2 | L42: =IF(N42="Oferta",J42*$D$60,J42) | M42: 46157 | N42: Oferta | O42: https://www.aguacircular.cl/01281-060-06
A43: VI | B43: Rancagua | C43: Río Cachapoal | D43: Canal | E43: San Pedro, Población | F43: 119 | G43: L/s | H43: 119 | I43: 453540 | J43: =I43/H43 | K43: =J43*1000/$K$2 | L43: =IF(N43="Oferta",J43*$D$60,J43) | M43: 46157 | N43: Oferta | O43: https://www.aguacircular.cl/00532-060-06
...

Sheet suelos
A1: fecha | B1: UF | C1: CLIENTE | D1: Región | E1: Comuna | F1: Rol | G1: Uso de Suelo | H1: Clase | I1: m2 | J1: Valor X UF/ m2 | K1: Valor Total | L1: Valor UF X Has | M1: Valor UF Total | N1: OBSERVACIONES | O1: Tasador
A2: =PORTADA!H7 | B2: =UF | C2: =PORTADA!C14 | D2: =PORTADA!H12 | E2: =PORTADA!H11 | F2: =LEGAL!G6 | H2: ='SUELOS '!C46 | I2: ='SUELOS '!E46 | J2: ='SUELOS '!F46 | K2: ='SUELOS '!G46 | L2: =J2*10000 | M2: =L2*I2/10000 | O2: ='RESUMEN VALOR'!B26

Sheet derechos de agua 
A1: fecha | B1: UF | C1: CLIENTE | D1: Región | E1: Comuna | F1: ROL | G1: Acciones /Regadores | H1: Lts/seg | I1: Canal | J1: Valor X Lts/seg | K1: Valor Total | L1: Valor UF X L/s | M1: Valor UF Total | N1: TASADOR
A2: =PORTADA!H7 | B2: =UF | C2: =PORTADA!C14 | D2: =PORTADA!H12 | E2: =PORTADA!H11 | F2: ='AGUA '!C25 | G2: ='AGUA '!F25 | H2: ='AGUA '!G25 | I2: ='AGUA '!B25 | J2: ='AGUA '!I25 | K2: =J2*H2 | L2: =J2/B2 | M2: =L2*H2 | N2: ='RESUMEN VALOR'!B26

Sheet plantas
A1: FECHA TASACION: | B1: UF tasación | C1: CLIENTE | D1: Región | E1: Comuna | F1: Tipo de Cultivo | G1: Variedad | H1: Año Plantación | I1: Densidad plantación (plantas/ha) | J1: Ubicación / Rol | K1: ha | L1: $ Inversion xhas | M1: Años inversion | N1: Vida util (años) | O1: Vida Util Residual | P1: Castigo Comercial % | Q1: $xhas | R1: Total | S1: Total UF | T1: Estado / Observaciones
A2: =PORTADA!H7 | B2: =suelos!B2 | C2: =PORTADA!C14 | D2: =PORTADA!H12 | E2: =PORTADA!H11 | F2: =PLANT!C37 | G2: =PLANT!D37 | H2: =PLANT!F37 | I2: =PLANT!I37 | J2: =PLANT!B37 | K2: =PLANT!J37 | L2: =ROUND(PLANT!W37*USD,-5) | M2: =IF(L2>K2,K2,L2) | N2: 40 | O2: =IF(H2=0,"",N2-(YEAR(PORTADA!$H$7)-H2)) | Q2: =PLANT!AA37 | R2: =Q2*K2 | S2: =R2/B2 | T2: =PLANTACION!K5
A3: =PORTADA!H7 | B3: =PORTADA!$H$8 | C3: =PORTADA!C14 | D3: =PORTADA!H12 | E3: =PORTADA!H11 | F3: =PLANT!C38 | G3: =PLANT!D38 | H3: =PLANT!F38 | I3: =PLANT!I38 | J3: =PLANT!B38 | K3: =PLANT!J38 | L3: =ROUND(PLANT!W38*USD,-5) | N3: 40 | O3: =IF(H3=0,"",N3-(YEAR(PORTADA!$H$7)-H3)) | Q3: =PLANT!AA38 | R3: =Q3*K3 | S3: =R3/B3 | T3: =PLANTACION!K6
A4: =PORTADA!H7 | B4: =PORTADA!$H$8 | C4: =PORTADA!C14 | D4: =PORTADA!H12 | E4: =PORTADA!H11 | F4: =PLANT!C39 | G4: =PLANT!D39 | H4: =PLANT!F39 | I4: =PLANT!I39 | J4: =PLANT!B39 | K4: =PLANT!J39 | L4: =ROUND(PLANT!W39*USD,-5) | M4: =IF(L4>K4,K4,L4) | N4: 40 | O4: =IF(H4=0,"",N4-(YEAR(PORTADA!$H$7)-H4)) | Q4: =PLANT!AA39 | R4: =Q4*K4 | S4: =R4/B4 | T4: =PLANTACION!K7
A5: =PORTADA!H7 | B5: =PORTADA!$H$8 | C5: =PORTADA!C14 | D5: =PORTADA!H12 | E5: =PORTADA!H11 | F5: =PLANT!C40 | G5: =PLANT!D40 | H5: =PLANT!F40 | I5: =PLANT!I40 | J5: =PLANT!B40 | K5: =PLANT!J40 | L5: =ROUND(PLANT!W40*USD,-5) | N5: 40 | O5: =IF(H5=0,"",N5-(YEAR(PORTADA!$H$7)-H5)) | Q5: =PLANT!AA40 | R5: =Q5*K5 | S5: =R5/B5 | T5: =PLANTACION!K8
A6: =PORTADA!H7 | B6: =PORTADA!$H$8 | C6: =PORTADA!C14 | D6: =PORTADA!H12 | E6: =PORTADA!H11 | F6: =PLANT!C41 | G6: =PLANT!D41 | H6: =PLANT!F41 | I6: =PLANT!I41 | J6: =PLANT!B41 | K6: =PLANT!J41 | L6: =ROUND(PLANT!W41*USD,-5) | N6: 40 | O6: =IF(H6=0,"",N6-(YEAR(PORTADA!$H$7)-H6)) | Q6: =PLANT!AA41 | R6: =Q6*K6 | S6: =R6/B6 | T6: =PLANTACION!K9
A7: =PORTADA!H7 | B7: =PORTADA!$H$8 | C7: =PORTADA!C14 | D7: =PORTADA!H12 | E7: =PORTADA!H11 | F7: =PLANT!C42 | G7: =PLANT!D42 | H7: =PLANT!F42 | I7: =PLANT!I42 | J7: =PLANT!B42 | K7: =PLANT!J42 | L7: =ROUND(PLANT!W42*USD,-5) | N7: 40 | O7: =IF(H7=0,"",N7-(YEAR(PORTADA!$H$7)-H7)) | Q7: =PLANT!AA42 | R7: =Q7*K7 | S7: =R7/B7 | T7: =PLANTACION!K10
K8: =SUM(K2:K7) | R8: =SUM(R2:R7)

Sheet PLANT
C1: USD | D1: =PORTADA!H9
C3: Especie | D3: Opex Año | E3: Costo Planta | F3: Años Opex | G3: Plantación | H3: Prep Suelo
C4: Cerezo | D4: 2500 | E4: =ROUNDUP(4000/$D$1,1) | F4: 3 | G4: 0.25 | H4: 1000
C5: Ciruelo | D5: 2000 | E5: =ROUNDUP(4000/$D$1,1) | F5: 3 | G5: 0.25 | H5: 1000
C6: Avellano | D6: 1350 | E6: =ROUNDUP(2700/$D$1,1) | F6: 4 | G6: 0.2 | H6: 1500
C7: Manzano | D7: 2000 | E7: =ROUNDUP(4000/$D$1,1) | F7: 3 | G7: 0.25 | H7: 1000
C8: Peral | D8: 2000 | E8: 5 | F8: 3 | G8: 0.25 | H8: 1000
C9: Nogal | D9: 2200 | E9: =ROUNDUP(6000/$D$1,1) | F9: 3 | G9: 0.25 | H9: 1000
C10: Vid Vinifera | D10: 1000 | E10: =ROUNDDOWN(900/$D$1,1) | F10: 2 | G10: 0.1 | H10: 700
C11: Kiwi | D11: 2000 | E11: =ROUNDUP(4000/$D$1,1) | F11: 2 | G11: 0.25 | H11: 1000
C12: Palto convencional | D12: 2800 | E12: 5 | F12: 4 | G12: 0.25 | H12: 2500
C13: Palto Clonal | D13: 2800 | E13: 14 | F13: 4 | G13: 0.25 | H13: 2500
C14: Uva de mesa | D14: 2500 | E14: 1.3 | F14: 2 | G14: 0.15 | H14: 1000
C15: Uva de mesa® | D15: 2500 | E15: 2.5 | F15: 2 | G15: 0.15 | H15: 1000
C27: Estructura | D27: USD/estruc
C28: Parron estándar | D28: 7000
C29: Open Gable | D29: 10000
C30: Espaldera | D30: 3500
C31: Alambrado Tutor | D31: 1500
C32: No | D32: 0
A36: Predio | B36: ROL | C36: Especie | D36: Variedad | E36: Conducción | F36: Año Plantación | G36: eh (m) | H36: sh (m) | I36: Plantas x ha | J36: Superf. Plantada ha | K36: SUPERF CON RIEGO | L36: Estructura | M36: Riego | N36: Valor Planta | O36: Costo Plantación | P36: Preparación suelo | Q36: Costo Estructura | R36: Edad (años) | S36: Años Opex | T36: Opex a considerar | U36: Capex/año | V36: Capex Total | W36: Costo Reposición /ha | X36: % CASTIGO | Y36: Valor Ajustado/ha | Z36: VALOR TOTAL USD | AA36: VALOR Ch$/ha | AB36: VALOR TOTAL $
