Workbook
Name Comunas_III: 'Listas Validación'!$B$2:$B$10
Name Comunas_IV: 'Listas Validación'!$C$2:$C$16
Name Comunas_IX: 'Listas Validación'!$J$2:$J$33
Name Comunas_RM: 'Listas Validación'!$E$2:$E$35
Name Comunas_V: 'Listas Validación'!$D$2:$D$37
Name Comunas_VI: 'Listas Validación'!$F$2:$F$34
Name Comunas_VII: 'Listas Validación'!$G$2:$G$31
Name Comunas_VIII: 'Listas Validación'!$I$2:$I$34
Name Comunas_X: 'Listas Validación'!$L$2:$L$31
Name Comunas_XIV: 'Listas Validación'!$K$2:$K$13
Name Comunas_XVI: 'Listas Validación'!$H$2:$H$22
Name ListaRegiones: 'Listas Validación'!$A$2:$A$12
Name version: Portada!$I$7

Sheet Portada
A4: INFORME AGROECONÓMICO
I7: V.2024-1073
A8: ANTECEDENTES GENERALES
A10: Cliente | F10: RUT
A11: Ejecutivo | F11: Fecha Visita
A12: Sucursal | F12: Fecha Emisión Informe
A13: Empresa | B13: Fitogreen | F13: N° Solicitud
A14: Agrónomo Informante | F14: Valor UF
A17: ESTRUCTURA PRODUCTIVA (TEMPORADA)
A19: Especie | B19: Escala Productiva Actual | D19: Consolidación productiva | F19: Condición de Tenencia de los Suelos (ha)
B20: Superficie (ha) | D20: % | F20: Propio | H20: Arriendo | I20: Otros
A21: ='Flujo proyectado '!A25 -> 0 | B21: =SUMIF(Plantaciones!$A$15:$A$15,Portada!A21,Plantaciones!$D$15:$D$15) -> 0 | D21: =IFERROR('Flujo proyectado '!F27/MAX('Flujo proyectado '!F27:M27),0) -> 0 | F21: =SUMIF(Plantaciones!$A$15:$A$15,Portada!A21,Plantaciones!$B$15:$B$15) -> 0 | H21: =SUMIF(Plantaciones!$A$15:$A$15,Portada!A21,Plantaciones!$C$15:$C$15) -> 0
A22: Total (ha) | B22: =SUM(B21:C21) -> 0 | F22: =SUM(F21:G21) -> 0
A24: RESUMEN RESULTADOS DE TEMPORADA
A26: ITEM | B26: Última temporada | E26: =RIGHT('Flujo proyectado '!$E$7,5) | F26: Proyección Corto Plazo | I26: =RIGHT('Flujo proyectado '!$F$7,5)
B27: M$ CLP | D27: UF | F27: M$ CLP | H27: UF
A28: Ingresos Operacionales | B28: ='Flujo proyectado '!E65 -> #DIV/0! | D28: =B28/$H$14*1000 -> #DIV/0! | F28: ='Flujo proyectado '!F65 -> 0 | H28: =F28/$H$14*1000 -> #DIV/0!
A29: Costos Directos | B29: ='Flujo proyectado '!E66 -> #DIV/0! | D29: =B29/$H$14*1000 -> #DIV/0! | F29: ='Flujo proyectado '!F66 -> 0 | H29: =F29/$H$14*1000 -> #DIV/0!
A30: Margen Bruto | B30: =B28-B29 -> #DIV/0! | D30: =B30/$H$14*1000 -> #DIV/0! | F30: =F28-F29 -> 0 | H30: =F30/$H$14*1000 -> #DIV/0!
A31: Costos Indirectos | B31: ='Flujo proyectado '!E67 -> #DIV/0! | D31: =B31/$H$14*1000 -> #DIV/0! | F31: ='Flujo proyectado '!F67 -> 0 | H31: =F31/$H$14*1000 -> #DIV/0!
A32: RESULTADO NETO | B32: =B30-B31 -> #DIV/0! | D32: =B32/$H$14*1000 -> #DIV/0! | F32: =F30-F31 -> 0 | H32: =F32/$H$14*1000 -> #DIV/0!
B34: Proyección
A35: Temporada | B35: ='Flujo proyectado '!F57 | C35: ='Flujo proyectado '!G57 | D35: ='Flujo proyectado '!H57 | E35: ='Flujo proyectado '!I57 | F35: ='Flujo proyectado '!J57 | G35: ='Flujo proyectado '!K57 | H35: ='Flujo proyectado '!L57 | I35: ='Flujo proyectado '!M57
A36: EBITDA M$ CLP | B36: ='Flujo proyectado '!F71 -> 0 | C36: ='Flujo proyectado '!G71 -> 0 | D36: ='Flujo proyectado '!H71 -> 0 | E36: ='Flujo proyectado '!I71 -> 0 | F36: ='Flujo proyectado '!J71 -> 0 | G36: ='Flujo proyectado '!K71 -> 0 | H36: ='Flujo proyectado '!L71 -> 0 | I36: ='Flujo proyectado '!M71 -> 0
A38: IMAGEN EMPLAZAMIENTO UNIDAD PRINCIPAL

Sheet Recursos
A2: DOTACIÓN DE RECURSOS
A4: SUELOS
A6: DATOS LEGALES TERRENOS
A7: Unidad Predial | B7: Nombre Lote | D7: Dominio | E7: Rol | F7: Región | G7: Comuna | H7: fojas | I7: n° | J7: año | K7: CBR | L7: Sup. Legal (ha) | M7: Sup. Real (ha)
L9: =SUM(L8:L8) -> 0 | M9: =SUM(M8:M8) -> 0
A11: CLASIFICACIÓN DE SUELOS
A12: Unidad Predial | B12: I - II r | C12: III -IV r | D12: I - II s | E12: III - IV s | F12: V - VI s | G12: VII -VIII s | H12: Total Riego | I12: Total Secano | J12: Superf. Total | K12: Topografía predominante
H13: =SUM(B13:C13) -> 0 | I13: =SUM(E13:G13) -> 0 | J13: =H13+I13 -> 0
A14: Total (ha) | C14: =SUM(C13:C13) -> 0 | D14: =SUM(D13:D13) -> 0 | E14: =SUM(E13:E13) -> 0 | F14: =SUM(F13:F13) -> 0 | G14: =SUM(G13:G13) -> 0 | H14: =SUM(H13:H13) -> 0 | I14: =SUM(I13:I13) -> 0 | J14: =SUM(J13:J13) -> 0
A20: AGUAS DE RIEGO
A22: Unidad Predial | B22: Fuente | C22: Nombre de la fuente | D22: Ejercicio del Derecho | F22: Dominio | G22: Cantidad (D°/acciones) | H22: Caudal nominal L/s | I22: Caudal Real L/s | J22: Datos Inscripción CBR
J23: Fojas | K23: Número | L23: Año | M23: CBR
A24: =A13 -> 0 | H24: =G24 -> 0 | I24: =H24 -> 0
A25: TOTAL AGUAS DISPONIBLES | H25: =SUM(H24:H24) -> 0 | I25: =SUM(I24:I24) -> 0
A31: ESTIMACIÓN REQUERIMIENTO AGUAS DE RIEGO
A33: Unidad Predial: | B33: =A24 -> 0 | D33: Comuna: | E33: =VLOOKUP(B33,$A$8:$G$9,7,FALSE) -> #N/A
A34: Especie | B34: Superficie (ha) | C34: Sistema de Riego | D34: Eficiencia Sistema de Riego | E34: ETo Máximo-mm (enero) | F34: Coef. Cultivo Kc (enero) | G34: Demanda Q Máximo L/s/ha | H34: Demanda Total por Plantación L/s | I34: Demanda Máxima Total Predio L/s | J34: Capacidad Tranques prediales (m3) | K34: Caudal Equivalente 90 días (L/s) | L34: Caudal Total Disponible (L/s) | M34: Balance Hídrico %
A35: {=IFERROR(INDEX(_xlfn.UNIQUE(_xlfn._xlws.FILTER(Plantaciones!$A$7:$A$8,TRIM(Plantaciones!$G$7:$G$8)=TRIM($B$33))),ROWS($A$35:A35)),"")} | B35: =IF(A35="","",SUMIFS(Plantaciones!$E$7:$E$7,Plantaciones!$A$7:$A$7,Recursos!A35,Plantaciones!$G$7:$G$7,Recursos!$B$33)) | D35: =IFERROR(VLOOKUP(C35,Opciones!$A$16:$B$20,2,FALSE),) -> 0 | E35: =IFERROR(INDEX(ETo!$I$6:$I$290,MATCH(E33,ETo!$C$6:$C$290,0)),"Comuna no encontrada") -> Comuna no encontrada | F35: =IF(A35="","",IFERROR(INDEX(ETo!$C$301:$C$355,MATCH(A35,ETo!$B$301:$B$355,0)),"Especie no encontrada")) | G35: =IFERROR(ROUND(E35*F35*10/D35/86.4,2),0) -> 0 | H35: =ROUND(G35*B35,2) -> #VALUE! | I35: =SUM(H35:H35) -> #VALUE! | K35: =TRUNC(J35*0.8/(86.4*90),2) -> 0 | L35: =SUMIF($A$24:$A$24,B33,$I$24:$I$24)+K35 -> 0 | M35: =IF(I35=0,IF(L35=0,0,"Sin demanda"),(L35-I35)/I35) -> #VALUE!
A36: Superficie Total Plantada | B36: =SUM(B35:B35) -> 0
A38: COMENTARIOS DOTACIÓN DE RECURSOS

Sheet Inversión
A2: INVERSIONES
A4: Proyecto | B4: Año | C4: Superficie (ha) | D4: Item | E4: Cantidad/ha | F4: Costo unitario USD | G4: Costo unitario USD/ha | H4: Costo Inversión Total USD | I4: Costo Inversión $ | J4: % En relación al Total
A15: Total | C15: =SUM(C5:C14) -> 0 | G15: =SUM(G5:G14) -> 0 | H15: =SUM(H5:H14) -> 0 | I15: =SUM(I5:I14) -> 0
A17: COMENTARIOS INVERSIONES

Sheet Plantaciones
A2: ESTRUCTURA PRODUCTIVA
A4: ="PLANTACIONES AL "&IF(ISNUMBER(Portada!$H$12),YEAR(Portada!$H$12),"") -> PLANTACIONES AL
A6: Especie | B6: Variedad | C6: Año Plantación | D6: Royalty | E6: Superficie (ha) | F6: Sistema Conducción | G6: Predio | H6: Riego | I6: Estatus Productivo | J6: Densidad o marco de plantación | K6: Dominio
A10: Superficie Total Plantada (ha) | E10: =SUM(E7:E9) -> 0
A12: RESUMEN SUPERFICIE PLANTADA
A14: Especie o rubro | B14: Propietario | C14: Arrendatario | D14: Total (ha) | E14: % por especie | F14: Plena | G14: Creciente | H14: Formación | I14: Proyecto | J14: Total (ha) | K14: % por especie con proyecto
A15: {=IFERROR(INDEX(_xlfn.UNIQUE(_xlfn._xlws.FILTER($A$7:$A$9,$A$7:$A$9<>"")),ROWS($A$15:A15)),"")} | B15: =SUMIFS($E$7:$E$7,$A$7:$A$7,A15,$K$7:$K$7,$B$14) -> 0 | C15: =SUMIFS($E$7:$E$7,$A$7:$A$7,A15,$K$7:$K$7,$C$14) -> 0 | D15: =SUM(B15:C15) -> 0 | E15: =D15/$D$16 -> #DIV/0! | F15: =SUMIFS($E$7:$E$7,$A$7:$A$7,A15,$I$7:$I$7,$F$14) -> 0 | G15: =SUMIFS($E$7:$E$7,$A$7:$A$7,A15,$I$7:$I$7,$G$14) -> 0 | H15: =SUMIFS($E$7:$E$7,$A$7:$A$7,A15,$I$7:$I$7,$H$14) -> 0 | J15: =SUM(F15:I15) -> 0 | K15: =J15/$D$16 -> #DIV/0!
A16: Total | B16: =SUM(B15:B15) -> 0 | C16: =SUM(C15:C15) -> 0 | D16: =SUM(D15:D15) -> 0 | E16: =SUM(E15:E15) -> #DIV/0! | F16: =SUM(F15:F15) -> 0 | G16: =SUM(G15:G15) -> 0 | H16: =SUM(H15:H15) -> 0 | I16: =SUM(I15:I15) -> 0 | ... K16: =SUM(K15:K15) -> #DIV/0!
A17: Porcentajes (%) | B17: =IFERROR(B16/$D$16,0) -> 0 | C17: =IFERROR(C16/$D$16,0) -> 0 | F17: =F16/$J$16 -> #DIV/0! | G17: =G16/$J$16 -> #DIV/0! | H17: =H16/$J$16 -> #DIV/0! | I17: =I16/$J$16 -> #DIV/0! | J17: =J16/$J$16 -> #DIV/0!
A19: Comentarios Plantaciones:
A30: SISTEMA DE PRODUCCIÓN EMPLEADO Y DESCRIPCIÓN CUALITATIVA DE LAS PLANTACIONES
A32: Especie | B32: Sistema de producción | C32: Densidad de plantación | D32: Sistema de riego | E32: Variedades con Royalty (%) | F32: Considera Techos o similares | G32: Sistema Contra heladas | H32: Nivel Tecnológico | I32: Nivel Homogeneidad | J32: Estado Fitosanitario | K32: Nivel Productivo Promedio
A33: =A15 | E33: =SUMIFS($E$7:$E$7,$A$7:$A$7,A33,$D$7:$D$7,"Sí")/$D$15 -> #DIV/0!
A36: SISTEMA DE COMERCIALIZACIÓN
A38: Especie | B38: Destino Principal | C38: Principales Empresas Comercializadoras | E38: Sistema de venta principal | F38: Certificaciones Productivas Vigentes | H38: Proceso de Packing | I38: Proceso de exportación | J38: Periodo Cosecha | K38: Periodo Liquidaciones
A39: =A33

Sheet Flujo proyectado 
A2: PROYECCIÓN LARGO PLAZO
A3: Tipo de cambio: | C3: $/USD | D3: =D7 | E3: =IF($E$7="","",$E$7) | F3: Proyección
E4: ='Anexo 1 Resultado'!F3 -> 0
D6: Históricos (Reales) | F6: Proyección
A7: Especie | B7: Variedad | C7: Año | D7: =IF($E$7="","",(LEFT($E$7,4)-1)&"/"&RIGHT(LEFT($E$7,4),2)) | F7: =IF($E$7="","",(LEFT($E$7,4)+1)&"/"&RIGHT(LEFT($E$7,4)+2,2)) | G7: =IF($E$7="","",(LEFT($E$7,4)+2)&"/"&RIGHT(LEFT($E$7,4)+3,2)) | H7: =IF($E$7="","",(LEFT($E$7,4)+3)&"/"&RIGHT(LEFT($E$7,4)+4,2)) | I7: =IF($E$7="","",(LEFT($E$7,4)+4)&"/"&RIGHT(LEFT($E$7,4)+5,2)) | J7: =IF($E$7="","",(LEFT($E$7,4)+5)&"/"&RIGHT(LEFT($E$7,4)+6,2)) | K7: =IF($E$7="","",(LEFT($E$7,4)+6)&"/"&RIGHT(LEFT($E$7,4)+7,2)) | L7: =IF($E$7="","",(LEFT($E$7,4)+7)&"/"&RIGHT(LEFT($E$7,4)+8,2)) | M7: =IF($E$7="","",(LEFT($E$7,4)+8)&"/"&RIGHT(LEFT($E$7,4)+9,2))
A8: =Plantaciones!A7 -> 0 | B8: =Plantaciones!B7 -> 0 | C8: =Plantaciones!C7 -> 0
A9: Superficie (ha) | F9: =Plantaciones!E7 -> 0 | G9: =F9 -> 0 | H9: =G9 -> 0 | I9: =H9 -> 0 | J9: =I9 -> 0 | K9: =J9 -> 0 | L9: =K9 -> 0 | M9: =L9 -> 0
A10: Precio exportación (USD/Kg) | F10: =Supuestos!$F$24*(1+Supuestos!$B$5) -> 0 | G10: =Supuestos!$G$24*(1+Supuestos!$B$5) -> 0 | H10: =Supuestos!$G$24*(1+Supuestos!$B$5) -> 0 | I10: =Supuestos!$G$24*(1+Supuestos!$B$5) -> 0 | J10: =Supuestos!$G$24*(1+Supuestos!$B$5) -> 0 | K10: =Supuestos!$G$24*(1+Supuestos!$B$5) -> 0 | L10: =Supuestos!$G$24*(1+Supuestos!$B$5) -> 0 | M10: =Supuestos!$G$24*(1+Supuestos!$B$5) -> 0
A11: Precio Mercado Interno (USD/Kg) | F11: =Supuestos!$H$24*(1+Supuestos!$B$6) -> 0 | G11: =Supuestos!$H$24*(1+Supuestos!$B$6) -> 0 | H11: =Supuestos!$H$24*(1+Supuestos!$B$6) -> 0 | I11: =Supuestos!$H$24*(1+Supuestos!$B$6) -> 0 | J11: =Supuestos!$H$24*(1+Supuestos!$B$6) -> 0 | K11: =Supuestos!$H$24*(1+Supuestos!$B$6) -> 0 | L11: =Supuestos!$H$24*(1+Supuestos!$B$6) -> 0 | M11: =Supuestos!$H$24*(1+Supuestos!$B$6) -> 0
A12: Producción/Rendimiento (Kg/ha) | F12: =Supuestos!K24*(1+Supuestos!$B$7) -> 0 | G12: =Supuestos!L24*(1+Supuestos!$B$7) -> 0 | H12: =Supuestos!M24*(1+Supuestos!$B$7) -> 0 | I12: =Supuestos!N24*(1+Supuestos!$B$7) -> 0 | J12: =Supuestos!O24*(1+Supuestos!$B$7) -> 0 | K12: =Supuestos!P24*(1+Supuestos!$B$7) -> 0 | L12: =Supuestos!Q24*(1+Supuestos!$B$7) -> 0 | M12: =Supuestos!R24*(1+Supuestos!$B$7) -> 0
A13: Ratio Exportación (%) | F13: =Supuestos!$E$24 -> 0 | G13: =Supuestos!$E$24 -> 0 | H13: =Supuestos!$E$24 -> 0 | I13: =Supuestos!$E$24 -> 0 | J13: =Supuestos!$E$24 -> 0 | K13: =Supuestos!$E$24 -> 0 | L13: =Supuestos!$E$24 -> 0 | M13: =Supuestos!$E$24 -> 0
A14: Costos (USD/ha) | F14: =IF(ISNUMBER(Supuestos!$S$24),Supuestos!$S$24,(Supuestos!$I$24+Supuestos!$J$24*F12))*(1+Supuestos!$B$8) -> 0 | G14: =IF(ISNUMBER(Supuestos!$T$24),Supuestos!$T$24,(Supuestos!$I$24+Supuestos!$J$24*G12))*(1+Supuestos!$B$8) -> 0 | H14: =IF(ISNUMBER(Supuestos!$U$24),Supuestos!$U$24+N(Supuestos!$V$24)*H12,(Supuestos!$I$24+Supuestos!$J$24*H12))*(1+Supuestos!$B$8) -> 0 | I14: =(Supuestos!$I$24+Supuestos!$J$24*I12)*(1+Supuestos!$B$8) -> 0 | J14: =(Supuestos!$I$24+Supuestos!$J$24*J12)*(1+Supuestos!$B$8) -> 0 | K14: =(Supuestos!$I$24+Supuestos!$J$24*K12)*(1+Supuestos!$B$8) -> 0 | L14: =(Supuestos!$I$24+Supuestos!$J$24*L12)*(1+Supuestos!$B$8) -> 0 | M14: =(Supuestos!$I$24+Supuestos!$J$24*M12)*(1+Supuestos!$B$8) -> 0
A15: Producción Total (kg) | D15: =D9*D12 -> 0 | E15: =E9*E12 -> 0 | F15: =F9*F12 -> 0 | G15: =G9*G12 -> 0 | H15: =H9*H12 -> 0 | I15: =I9*I12 -> 0 | J15: =J9*J12 -> 0 | K15: =K9*K12 -> 0 | ... M15: =M9*M12 -> 0
A16: Ingresos Exportación | D16: =D15*D13*D10 -> 0 | E16: =E15*E13*E10 -> 0 | F16: =F15*F13*F10 -> 0 | G16: =G15*G13*G10 -> 0 | H16: =H15*H13*H10 -> 0 | I16: =I15*I13*I10 -> 0 | J16: =J15*J13*J10 -> 0 | K16: =K15*K13*K10 -> 0 | ... M16: =M15*M13*M10 -> 0
A17: Ingresos Mercado Interno | D17: =D15*(1-D13)*D11 -> 0 | E17: =E15*(1-E13)*E11 -> 0 | F17: =F15*(1-F13)*F11 -> 0 | G17: =G15*(1-G13)*G11 -> 0 | H17: =H15*(1-H13)*H11 -> 0 | I17: =I15*(1-I13)*I11 -> 0 | J17: =J15*(1-J13)*J11 -> 0 | K17: =K15*(1-K13)*K11 -> 0 | ... M17: =M15*(1-M13)*M11 -> 0
A22: RESUMEN DE INDICADORES GENERALES | D22: Históricos (Reales) | F22: Proyección
D23: =D$7 | E23: =IF($E$7="","",$E$7) | F23: =F$7 | G23: =G$7 | H23: =H$7 | I23: =I$7 | J23: =J$7 | K23: =K$7 | L23: =L$7 | M23: =M$7
A24: Superficie (ha) | D24: =SUM(D25:D25) -> 0 | E24: =SUM(E25:E25) -> 0 | F24: =SUM(F25:F25) -> 0 | G24: =SUM(G25:G25) -> 0 | H24: =SUM(H25:H25) -> 0 | I24: =SUM(I25:I25) -> 0 | J24: =SUM(J25:J25) -> 0 | K24: =SUM(K25:K25) -> 0 | ... M24: =SUM(M25:M25) -> 0
D25: =D9 -> 0 | E25: =F25 -> 0 | F25: =F9 -> 0 | G25: =G9 -> 0 | H25: =H9 -> 0 | I25: =I9 -> 0 | J25: =J9 -> 0 | K25: =K9 -> 0 | L25: =L9 -> 0 | M25: =M9 -> 0
A26: Producción Total (kg) | D26: =SUM(D27:D27) -> 0 | E26: =SUM(E27:E27) -> 0 | F26: =SUM(F27:F27) -> 0 | G26: =SUM(G27:G27) -> 0 | H26: =SUM(H27:H27) -> 0 | I26: =SUM(I27:I27) -> 0 | J26: =SUM(J27:J27) -> 0 | K26: =SUM(K27:K27) -> 0 | ... M26: =SUM(M27:M27) -> 0
A27: =A25 -> 0 | D27: =D15 -> 0 | E27: ='Anexo 1 Resultado'!B5 -> 0 | F27: =F15 -> 0 | G27: =G15 -> 0 | H27: =H15 -> 0 | I27: =I15 -> 0 | J27: =J15 -> 0 | K27: =K15 -> 0 | L27: =L15 -> 0 | M27: =M15 -> 0
A28: Producción promedio (kg/ha)
A29: =A27 -> 0 | D29: =IFERROR(D27/D25,0) -> 0 | E29: =IFERROR(E27/E25,0) -> 0 | F29: =IFERROR(F27/F25,0) -> 0 | G29: =IFERROR(G27/G25,0) -> 0 | H29: =IFERROR(H27/H25,0) -> 0 | I29: =IFERROR(I27/I25,0) -> 0 | J29: =IFERROR(J27/J25,0) -> 0 | K29: =IFERROR(K27/K25,0) -> 0 | ... M29: =IFERROR(M27/M25,0) -> 0
A30: Precio de venta promedio (USD/kg)
A31: =A29 -> 0 | D31: =IFERROR(D42/D27,0) -> 0 | E31: =IFERROR(E42/E27,0) -> 0 | F31: =IFERROR(F42/F27,0) -> 0 | G31: =IFERROR(G42/G27,0) -> 0 | H31: =IFERROR(H42/H27,0) -> 0 | I31: =IFERROR(I42/I27,0) -> 0 | J31: =IFERROR(J42/J27,0) -> 0 | K31: =IFERROR(K42/K27,0) -> 0 | ... M31: =IFERROR(M42/M27,0) -> 0
A32: Costo Promedio (USD/ha)
A33: =A31 -> 0 | D33: =IFERROR(D44/D25,0) -> 0 | E33: =IFERROR(E44/E25,0) -> 0 | F33: =IFERROR(F44/F25,0) -> 0 | G33: =IFERROR(G44/G25,0) -> 0 | H33: =IFERROR(H44/H25,0) -> 0 | I33: =IFERROR(I44/I25,0) -> 0 | J33: =IFERROR(J44/J25,0) -> 0 | K33: =IFERROR(K44/K25,0) -> 0 | ... M33: =IFERROR(M44/M25,0) -> 0
A34: Costo unitario (USD/Kg)
A35: =A33 -> 0 | D35: =IFERROR(D44/D27,0) -> 0 | E35: =IFERROR(E44/E27,0) -> 0 | F35: =IFERROR(F44/F27,0) -> 0 | G35: =IFERROR(G44/G27,0) -> 0 | H35: =IFERROR(H44/H27,0) -> 0 | I35: =IFERROR(I44/I27,0) -> 0 | J35: =IFERROR(J44/J27,0) -> 0 | K35: =IFERROR(K44/K27,0) -> 0 | ... M35: =IFERROR(M44/M27,0) -> 0
A36: Margen bruto (USD/ha)
A37: =A35 -> 0 | D37: =IFERROR((D42-D44)/D25,0) -> 0 | E37: =IFERROR((E42-E44)/E25,0) -> 0 | F37: =IFERROR((F42-F44)/F25,0) -> 0 | G37: =IFERROR((G42-G44)/G25,0) -> 0 | H37: =IFERROR((H42-H44)/H25,0) -> 0 | I37: =IFERROR((I42-I44)/I25,0) -> 0 | J37: =IFERROR((J42-J44)/J25,0) -> 0 | K37: =IFERROR((K42-K44)/K25,0) -> 0 | ... M37: =IFERROR((M42-M44)/M25,0) -> 0
A39: ESTADO DE RESULTADOS | D39: Históricos (Reales) | F39: Proyección
D40: =D$7 | E40: =IF($E$7="","",$E$7) | F40: =F$7 | G40: =G$7 | H40: =H$7 | I40: =I$7 | J40: =J$7 | K40: =K$7 | L40: =L$7 | M40: =M$7
A41: Ingresos Totales | D41: =SUM(D42:D42) -> 0 | E41: =SUM(E42:E42) -> #DIV/0! | F41: =SUM(F42:F42) -> 0 | G41: =SUM(G42:G42) -> 0 | H41: =SUM(H42:H42) -> 0 | I41: =SUM(I42:I42) -> 0 | J41: =SUM(J42:J42) -> 0 | K41: =SUM(K42:K42) -> 0 | ... M41: =SUM(M42:M42) -> 0
A42: =A35 -> 0 | D42: =D16+D17 -> 0 | E42: ='Anexo 1 Resultado'!G5/'Anexo 1 Resultado'!$F$3 -> #DIV/0! | F42: =F16+F17 -> 0 | G42: =G16+G17 -> 0 | H42: =H16+H17 -> 0 | I42: =I16+I17 -> 0 | J42: =J16+J17 -> 0 | K42: =K16+K17 -> 0 | L42: =L16+L17 -> 0 | M42: =M16+M17 -> 0
A43: Costos Directos Totales | D43: =SUM(D44:D44) -> 0 | E43: =SUM(E44:E44) -> #DIV/0! | F43: =SUM(F44:F44) -> 0 | G43: =SUM(G44:G44) -> 0 | H43: =SUM(H44:H44) -> 0 | I43: =SUM(I44:I44) -> 0 | J43: =SUM(J44:J44) -> 0 | K43: =SUM(K44:K44) -> 0 | ... M43: =SUM(M44:M44) -> 0
A44: =A42 -> 0 | E44: ='Anexo 1 Resultado'!H5/'Anexo 1 Resultado'!$F$3 -> #DIV/0! | F44: =F9*F14 -> 0 | G44: =G9*G14 -> 0 | H44: =H9*H14 -> 0 | I44: =I9*I14 -> 0 | J44: =J9*J14 -> 0 | K44: =K9*K14 -> 0 | L44: =L9*L14 -> 0 | M44: =M9*M14 -> 0
A46: Costos Indirectos | D46: =SUM(D47:D48) -> 0 | E46: =SUM(E47:E48) -> #DIV/0! | F46: =SUM(F47:F48) -> 0 | G46: =SUM(G47:G48) -> 0 | H46: =SUM(H47:H48) -> 0 | I46: =SUM(I47:I48) -> 0 | J46: =SUM(J47:J48) -> 0 | K46: =SUM(K47:K48) -> 0 | ... M46: =SUM(M47:M48) -> 0
A47: Administración | E47: ='Anexo 1 Resultado'!I7/'Anexo 1 Resultado'!$F$3 -> #DIV/0! | F47: =Supuestos!$B$10 -> 0 | G47: =Supuestos!$B$10 -> 0 | H47: =Supuestos!$B$10 -> 0 | I47: =Supuestos!$B$10 -> 0 | J47: =Supuestos!$B$10 -> 0 | K47: =Supuestos!$B$10 -> 0 | L47: =Supuestos!$B$10 -> 0 | M47: =Supuestos!$B$10 -> 0
A48: Gastos Generales | E48: ='Anexo 1 Resultado'!I8/'Anexo 1 Resultado'!$F$3 -> #DIV/0!
...

Sheet Supuestos
A1: SUPUESTOS DE PROYECCIÓN – parámetros utilizados en el flujo (USD)
A2: Rendimiento en kg/ha; precios en USD/kg; costos fijos en USD/ha y variables en USD/kg producido. Azul = dato de entrada; verde = vínculo a otra hoja.
A4: SENSIBILIZACIÓN (Δ %)
A5: Δ Precio exportación | B5: 0
A6: Δ Precio mercado interno | B6: 0
A7: Δ Rendimiento (kg/ha) | B7: 0
A8: Δ Costos (USD/ha) | B8: 0
A10: Administración general (USD/año)
D12: Histórico (real) | F12: Proyección
A13: RESULTADO DEL FLUJO (USD) | D13: ='Flujo proyectado '!D57 | E13: ='Flujo proyectado '!E57 | F13: ='Flujo proyectado '!F57 | G13: ='Flujo proyectado '!G57 | H13: ='Flujo proyectado '!H57 | I13: ='Flujo proyectado '!I57 | J13: ='Flujo proyectado '!J57 | K13: ='Flujo proyectado '!K57 | ... M13: ='Flujo proyectado '!M57
A14: Ingresos totales | D14: ='Flujo proyectado '!D52 -> 0 | E14: ='Flujo proyectado '!E52 -> #DIV/0! | F14: ='Flujo proyectado '!F52 -> 0 | G14: ='Flujo proyectado '!G52 -> 0 | H14: ='Flujo proyectado '!H52 -> 0 | I14: ='Flujo proyectado '!I52 -> 0 | J14: ='Flujo proyectado '!J52 -> 0 | K14: ='Flujo proyectado '!K52 -> 0 | ... M14: ='Flujo proyectado '!M52 -> 0
A15: Costos directos | D15: ='Flujo proyectado '!D53 -> 0 | E15: ='Flujo proyectado '!E53 -> #DIV/0! | F15: ='Flujo proyectado '!F53 -> 0 | G15: ='Flujo proyectado '!G53 -> 0 | H15: ='Flujo proyectado '!H53 -> 0 | I15: ='Flujo proyectado '!I53 -> 0 | J15: ='Flujo proyectado '!J53 -> 0 | K15: ='Flujo proyectado '!K53 -> 0 | ... M15: ='Flujo proyectado '!M53 -> 0
A16: Costos indirectos (administración) | D16: ='Flujo proyectado '!D54 -> 0 | E16: ='Flujo proyectado '!E54 -> #DIV/0! | F16: ='Flujo proyectado '!F54 -> 0 | G16: ='Flujo proyectado '!G54 -> 0 | H16: ='Flujo proyectado '!H54 -> 0 | I16: ='Flujo proyectado '!I54 -> 0 | J16: ='Flujo proyectado '!J54 -> 0 | K16: ='Flujo proyectado '!K54 -> 0 | ... M16: ='Flujo proyectado '!M54 -> 0
A17: EBITDA | D17: ='Flujo proyectado '!D58 -> 0 | E17: ='Flujo proyectado '!E58 -> #DIV/0! | F17: ='Flujo proyectado '!F58 -> 0 | G17: ='Flujo proyectado '!G58 -> 0 | H17: ='Flujo proyectado '!H58 -> 0 | I17: ='Flujo proyectado '!I58 -> 0 | J17: ='Flujo proyectado '!J58 -> 0 | K17: ='Flujo proyectado '!K58 -> 0 | ... M17: ='Flujo proyectado '!M58 -> 0
A18: EBITDA por hectárea (USD/ha) | D18: ='Flujo proyectado '!D59 -> 0 | E18: ='Flujo proyectado '!E59 -> 0 | F18: ='Flujo proyectado '!F59 -> 0 | G18: ='Flujo proyectado '!G59 -> 0 | H18: ='Flujo proyectado '!H59 -> 0 | I18: ='Flujo proyectado '!I59 -> 0 | J18: ='Flujo proyectado '!J59 -> 0 | K18: ='Flujo proyectado '!K59 -> 0 | ... M18: ='Flujo proyectado '!M59 -> 0
A19: EBITDA / Ingresos | D19: ='Flujo proyectado '!D60 -> 0 | E19: ='Flujo proyectado '!E60 -> 0 | F19: ='Flujo proyectado '!F60 -> 0 | G19: ='Flujo proyectado '!G60 -> 0 | H19: ='Flujo proyectado '!H60 -> 0 | I19: ='Flujo proyectado '!I60 -> 0 | J19: ='Flujo proyectado '!J60 -> 0 | K19: ='Flujo proyectado '!K60 -> 0 | ... M19: ='Flujo proyectado '!M60 -> 0
K22: Rendimiento (kg/ha)
A23: Especie | B23: Variedad | C23: Año plant. | D23: Sup. (ha) | E23: % export. | F23: ="Precio exp. "&'Flujo proyectado '!$F$7&" (USD/kg)" -> Precio exp. (USD/kg) | G23: ="Precio exp. "&'Flujo proyectado '!$G$7&"+ (USD/kg)" -> Precio exp. + (USD/kg) | H23: Precio mercado interno (USD/kg) | I23: Costo fijo (USD/ha) | J23: Costo variable (USD/kg) | K23: ='Flujo proyectado '!F$7 | L23: ='Flujo proyectado '!G$7 | M23: ='Flujo proyectado '!H$7 | N23: ='Flujo proyectado '!I$7 | O23: ='Flujo proyectado '!J$7 | P23: ='Flujo proyectado '!K$7 | Q23: ='Flujo proyectado '!L$7 | R23: ='Flujo proyectado '!M$7 | S23: Costo en formación año 1 (USD/ha) | T23: Costo en formación año 2 (USD/ha) | U23: Fijo año 3 de formación (USD/ha) | V23: Variable año 3 de formación (USD/kg)
A24: =Plantaciones!A7 -> 0 | B24: =Plantaciones!B7 -> 0 | C24: =Plantaciones!C7 -> 0 | D24: =Plantaciones!E7 -> 0
A25: ="Total "&LOWER($A$22) -> Total | D25: =SUM(D24:D24) -> 0

Sheet Comentarios generales Opinion
A2: COMENTARIOS GENERALES
A4: Gestión Administrativa y Productiva | E4: CALIFICACIÓN
A14: Conocimiento y Manejo de Canales Comerciales | E14: CALIFICACIÓN
A21: Calidad de los Activos Productivos Disponibles | E21: CALIFICACIÓN
A29: Conclusión Final | E29: CALIFICACIÓN

Sheet Anexo 1 Resultado
A1: ANEXO 1. Información aportada por el cliente sobre el desempeño real de la temporada anterior.
A3: RESULTADO REAL TEMPORADA | D3: =IF('Flujo proyectado '!$E$7="","",'Flujo proyectado '!$E$7) | E3: Valor Dólar
A4: Especie o Rubro | B4: Producción Total | C4: Unidad | D4: % Exportación | E4: Ventas Exportación ($) | F4: Ventas Merc. Interno ($) | G4: Total ventas ($) | H4: Costos Directos Totales por Rubro ($) | I4: Margen Bruto ($)
C5: kg | G5: =+E5+F5 -> 0 | I5: =+G5-H5 -> 0
E6: =SUM(E5:E5) -> 0 | F6: =SUM(F5:F5) -> 0 | G6: =SUM(G5:G5) -> 0 | H6: =SUM(H5:H5) -> 0 | I6: =SUM(I5:I5) -> 0
G7: Administración $
G8: Gastos Generales $
G9: EBITDA $ | I9: =I6-I7-I8 -> 0

Sheet Anexo 2 Ventas F29
A1: ANEXO 2. VENTAS SEGÚN DECLARACIONES MENSUALES DE IVA (FORMULARIO 29)
A2: =IF('Flujo proyectado '!$E$7="","Período julio – junio. Base imponible mensual declarada ante el SII, en pesos chilenos.","Período julio "&LEFT('Flujo proyectado '!$E$7,4)&" – junio "&IF('Flujo proyectado '!$E$7="","",LEFT('Flujo proyectado '!$E$7,4)+1)&". Base imponible mensual declarada ante el SII, en pesos chilenos.") -> Período julio – junio. Base imponible mensual declarada ante el SII, en pesos chilenos.
A4: Mes | B4: Ventas netas ($) | C4: Ventas netas (USD) | D4: % del total | E4: % acumulado
A5: ="Julio "&LEFT('Flujo proyectado '!$E$7,4) -> Julio | C5: =B5/$C$20 -> #DIV/0! | D5: =B5/$B$17 -> #DIV/0! | E5: =SUM($D$5:D5) -> #DIV/0!
A6: ="Agosto "&LEFT('Flujo proyectado '!$E$7,4) -> Agosto | C6: =B6/$C$20 -> #DIV/0! | D6: =B6/$B$17 -> #DIV/0! | E6: =SUM($D$5:D6) -> #DIV/0!
A7: ="Septiembre "&LEFT('Flujo proyectado '!$E$7,4) -> Septiembre | C7: =B7/$C$20 -> #DIV/0! | D7: =B7/$B$17 -> #DIV/0! | E7: =SUM($D$5:D7) -> #DIV/0!
A8: ="Octubre "&LEFT('Flujo proyectado '!$E$7,4) -> Octubre | C8: =B8/$C$20 -> #DIV/0! | D8: =B8/$B$17 -> #DIV/0! | E8: =SUM($D$5:D8) -> #DIV/0!
A9: ="Noviembre "&LEFT('Flujo proyectado '!$E$7,4) -> Noviembre | C9: =B9/$C$20 -> #DIV/0! | D9: =B9/$B$17 -> #DIV/0! | E9: =SUM($D$5:D9) -> #DIV/0!
A10: ="Diciembre "&LEFT('Flujo proyectado '!$E$7,4) -> Diciembre | C10: =B10/$C$20 -> #DIV/0! | D10: =B10/$B$17 -> #DIV/0! | E10: =SUM($D$5:D10) -> #DIV/0!
A11: ="Enero "&IF('Flujo proyectado '!$E$7="","",LEFT('Flujo proyectado '!$E$7,4)+1) -> Enero | C11: =B11/$C$20 -> #DIV/0! | D11: =B11/$B$17 -> #DIV/0! | E11: =SUM($D$5:D11) -> #DIV/0!
A12: ="Febrero "&IF('Flujo proyectado '!$E$7="","",LEFT('Flujo proyectado '!$E$7,4)+1) -> Febrero | C12: =B12/$C$20 -> #DIV/0! | D12: =B12/$B$17 -> #DIV/0! | E12: =SUM($D$5:D12) -> #DIV/0!
A13: ="Marzo "&IF('Flujo proyectado '!$E$7="","",LEFT('Flujo proyectado '!$E$7,4)+1) -> Marzo | C13: =B13/$C$20 -> #DIV/0! | D13: =B13/$B$17 -> #DIV/0! | E13: =SUM($D$5:D13) -> #DIV/0!
A14: ="Abril "&IF('Flujo proyectado '!$E$7="","",LEFT('Flujo proyectado '!$E$7,4)+1) -> Abril | C14: =B14/$C$20 -> #DIV/0! | D14: =B14/$B$17 -> #DIV/0! | E14: =SUM($D$5:D14) -> #DIV/0!
A15: ="Mayo "&IF('Flujo proyectado '!$E$7="","",LEFT('Flujo proyectado '!$E$7,4)+1) -> Mayo | C15: =B15/$C$20 -> #DIV/0! | D15: =B15/$B$17 -> #DIV/0! | E15: =SUM($D$5:D15) -> #DIV/0!
A16: ="Junio "&IF('Flujo proyectado '!$E$7="","",LEFT('Flujo proyectado '!$E$7,4)+1) -> Junio | C16: =B16/$C$20 -> #DIV/0! | D16: =B16/$B$17 -> #DIV/0! | E16: =SUM($D$5:D16) -> #DIV/0!
A17: Total 12 meses | B17: =SUM(B5:B16) -> 0 | C17: =SUM(C5:C16) -> #DIV/0! | D17: =SUM(D5:D16) -> #DIV/0!
A19: ="Venta temporada "&'Flujo proyectado '!$E$7&" informada" -> Venta temporada informada | B19: ='Anexo 1 Resultado'!G6 -> 0 | C19: =B19/$C$20 -> #DIV/0!
A20: Valor dólar utilizado ($/USD) | C20: ='Anexo 1 Resultado'!F3 -> 0
A21: Diferencia entre F29 y venta informada (%) | B21: =B17/B19-1 -> #DIV/0!

Sheet Anexo 3 Precios
A1: ANEXO 3. ANÁLISIS DE PRECIOS (LIQUIDACIONES Y CONTRATOS)
A3: Azul = dato tomado de los documentos; negro = fórmula; verde = vínculo a otra hoja. Precios en USD/kg. 'Modelo' = precio vigente en la hoja Supuestos (largo plazo).
A6: Grupo varietal | B6: Kilos netos | C6: USD/kg promedio | D6: Retorno final (USD) | E6: Precio modelo (USD/kg) | F6: Modelo vs. liquidación
F7: =IF(E7="","",IFERROR(E7/C7-1,""))
A8: Total exportado | B8: =SUM(B7:B7) -> 0 | C8: =IFERROR(D8/B8,"") | D8: =SUM(D7:D7) -> 0 | F8: =IF(E8="","",IFERROR(E8/C8-1,""))
A10: 2. RESUMEN POR ESPECIE
A11: Tema | B11: Texto sugerido

Sheet Anexo 4 Imágenes
A1: ANEXO 4. IMÁGENES DE LAS PLANTACIONES

Sheet Opciones
A2: Dominio
A3: Propietario
A4: Sociedad Relacionada
A5: Propiedad Familiar
A6: Arrendatario
A7: Usufructuario
A9: Ejercicio derechos de agua
A10: Permanente y continuo
A11: Permanente y discontinuo
A12: Eventual y continuo
A13: Eventual y discontinuo
A15: Sistema de riego y eficiencia | B15: %
A16: Goteo | B16: 0.9
A17: Microaspersión | B17: 0.8
A18: Aspersión o Pivote | B18: 0.7
A19: Surco | B19: 0.5
A20: Californiano | B20: 0.6

Sheet ETo
B1: Evapotranspiración de referencia (ETo) – Enero – por comuna, Regiones de Atacama a Los Lagos
B2: Fuente: CNR/CIREN, Evapotranspiración de Referencia para la determinación de las demandas de riego en Chile (Anexo 7.2). Valores medios climatológicos, FAO Penman-Monteith.
B3: Días de enero: | D3: 31
A5: n° Region | B5: Región | C5: Comuna | D5: Localidad(es) de referencia | E5: Tipo de asignación | F5: ETo enero (mm/día) | G5: ETo enero (mm/mes) | H5: ETo anual (mm/año) | I5: Eto Max +15% (mm/año)
A6: III | B6: Atacama | C6: Alto del Carmen | D6: El Toro | E6: Estimado – localidad cercana | F6: 7.2 | G6: =F6*$D$3 -> 223.2 | H6: 1878 | I6: =ROUND(F6*1.15,2) -> 8.28
A7: III | B7: Atacama | C7: Caldera | D7: Caldera | E7: Directo (cabecera comunal) | F7: 4.9 | G7: =F7*$D$3 -> 151.9 | H7: 1314 | I7: =ROUND(F7*1.15,2) -> 5.64
A8: III | B8: Atacama | C8: Chañaral | D8: Chañaral | E8: Directo (cabecera comunal) | F8: 5.1 | G8: =F8*$D$3 -> 158.1 | H8: 1357 | I8: =ROUND(F8*1.15,2) -> 5.87
A9: III | B9: Atacama | C9: Copiapó | D9: Copiapó | E9: Directo (cabecera comunal) | F9: 6.3 | G9: =F9*$D$3 -> 195.3 | H9: 1660 | I9: =ROUND(F9*1.15,2) -> 7.25
A10: III | B10: Atacama | C10: Diego de Almagro | D10: Pueblo Hundido (Diego de Almagro) | E10: Directo (cabecera comunal) | F10: 6.6 | G10: =F10*$D$3 -> 204.6 | H10: 1912 | I10: =ROUND(F10*1.15,2) -> 7.59
A11: III | B11: Atacama | C11: Freirina | D11: Freirina | E11: Directo (cabecera comunal) | F11: 5 | G11: =F11*$D$3 -> 155 | H11: 1231 | I11: =ROUND(F11*1.15,2) -> 5.75
A12: III | B12: Atacama | C12: Huasco | D12: Huasco | E12: Directo (cabecera comunal) | F12: 4.8 | G12: =F12*$D$3 -> 148.8 | H12: 1176 | I12: =ROUND(F12*1.15,2) -> 5.52
A13: III | B13: Atacama | C13: Tierra Amarilla | D13: Tierra Amarilla | E13: Directo (cabecera comunal) | F13: 6.8 | G13: =F13*$D$3 -> 210.8 | H13: 1794 | I13: =ROUND(F13*1.15,2) -> 7.82
A14: III | B14: Atacama | C14: Vallenar | D14: Vallenar | E14: Directo (cabecera comunal) | F14: 6 | G14: =F14*$D$3 -> 186 | H14: 1510 | I14: =ROUND(F14*1.15,2) -> 6.9
A15: IV | B15: Coquimbo | C15: Andacollo | D15: Andacollo | E15: Directo (cabecera comunal) | F15: 6 | G15: =F15*$D$3 -> 186 | H15: 1479 | I15: =ROUND(F15*1.15,2) -> 6.9
A16: IV | B16: Coquimbo | C16: Canela | D16: Canela Baja | E16: Directo (cabecera comunal) | F16: 5.1 | G16: =F16*$D$3 -> 158.1 | H16: 1247 | I16: =ROUND(F16*1.15,2) -> 5.87
A17: IV | B17: Coquimbo | C17: Combarbalá | D17: Combarbalá | E17: Directo (cabecera comunal) | F17: 6.8 | G17: =F17*$D$3 -> 210.8 | H17: 1669 | I17: =ROUND(F17*1.15,2) -> 7.82
... A290: X | B290: Los Lagos | C290: San Pablo | D290: San Pablo | E290: Directo (cabecera comunal) | F290: 3.9 | G290: =F290*$D$3 -> 120.9 | H290: 845 | I290: =ROUND(F290*1.15,2) -> 4.49
B292: Notas:
B293: 1. Directo: la fuente tiene un valor para la cabecera comunal (o su localidad equivalente, p. ej. Diego de Almagro = Pueblo Hundido, Río Hurtado = Samo Alto, Colbún = Panimávida).
B294: 2. Estimado (celda amarilla): la comuna no tiene localidad en la fuente; se asignó la localidad más cercana con condición similar (costa/valle/precordillera) o el promedio de dos localidades vecinas. Revisar si el predio está en un sector con altitud o influencia costera distinta.
B295: 3. Comunas urbanas del Gran Santiago se asignaron a la localidad Santiago, salvo La Pintana y Quilicura que tienen valor propio.
B296: 4. Se excluyen Juan Fernández e Isla de Pascua (sin datos en la fuente).
B297: 5. ETo mensual = ETo diaria × días de enero (celda C3). Valores en verde se leen desde la hoja 'Localidades (fuente)'.
B300: ESPECIE | C300: Kc
B301: Alcachofa | C301: 1
B302: Alfalfa | C302: 1.1
B303: Almendro | C303: 1.1
B304: Arándano | C304: 1.05
B305: Arroz | C305: 1.2
B306: Avellano | C306: 0.75
B307: Caqui | C307: 1.1
B308: Castaño | C308: 0.85
B309: Cebolla | C309: 1.05
B310: Cerezo | C310: 1
B311: Chirimoyo | C311: 0.8
B312: Ciruelo europeo | C312: 0.9
... B355: Uva vinífera | C355: 0.5

Sheet Listas Validación
A1: Regiones | B1: III | C1: IV | D1: V | E1: RM | F1: VI | G1: VII | H1: XVI | I1: VIII | J1: IX | K1: XIV | L1: X
A2: III | B2: Alto del Carmen | C2: Andacollo | D2: Algarrobo | E2: Alhué | F2: Chépica | G2: Cauquenes | H2: Bulnes | I2: Alto Biobío | J2: Angol | K2: Corral | L2: Ancud
A3: IV | B3: Caldera | C3: Canela | D3: Cabildo | E3: Buin | F3: Chimbarongo | G3: Chanco | H3: Chillán | I3: Antuco | J3: Carahue | K3: Futrono | L3: Calbuco
A4: V | B4: Chañaral | C4: Combarbalá | D4: Calle Larga | E4: Calera de Tango | F4: Codegua | G4: Colbún | H4: Chillán Viejo | I4: Arauco | J4: Cholchol | K4: La Unión | L4: Castro
A5: RM | B5: Copiapó | C5: Coquimbo | D5: Cartagena | E5: Cerrillos | F5: Coinco | G5: Constitución | H5: Cobquecura | I5: Cabrero | J5: Collipulli | K5: Lago Ranco | L5: Chaitén
A6: VI | B6: Diego de Almagro | C6: Illapel | D6: Casablanca | E6: Cerro Navia | F6: Coltauco | G6: Curepto | H6: Coelemu | I6: Cañete | J6: Cunco | K6: Lanco | L6: Chonchi
A7: VII | B7: Freirina | C7: La Higuera | D7: Catemu | E7: Colina | F7: Doñihue | G7: Curicó | H7: Coihueco | I7: Chiguayante | J7: Curacautín | K7: Los Lagos | L7: Cochamó
A8: XVI | B8: Huasco | C8: La Serena | D8: Concón | E8: Conchalí | F8: Graneros | G8: Empedrado | H8: El Carmen | I8: Concepción | J8: Curarrehue | K8: Máfil | L8: Curaco de Vélez
A9: VIII | B9: Tierra Amarilla | C9: Los Vilos | D9: El Quisco | E9: Curacaví | F9: La Estrella | G9: Hualañé | H9: Ninhue | I9: Contulmo | J9: Ercilla | K9: Mariquina | L9: Dalcahue
A10: IX | B10: Vallenar | C10: Monte Patria | D10: El Tabo | E10: El Bosque | F10: Las Cabras | G10: Licantén | H10: Ñiquén | I10: Coronel | J10: Freire | K10: Paillaco | L10: Fresia
A11: XIV | C11: Ovalle | D11: Hijuelas | E11: El Monte | F11: Litueche | G11: Linares | H11: Pemuco | I11: Curanilahue | J11: Galvarino | K11: Panguipulli | L11: Frutillar
A12: X | C12: Paiguano | D12: La Calera | E12: Estación Central | F12: Lolol | G12: Longaví | H12: Pinto | I12: Florida | J12: Gorbea | K12: Río Bueno | L12: Futaleufú
C13: Punitaqui | D13: La Cruz | E13: Huechuraba | F13: Machalí | G13: Maule | H13: Portezuelo | I13: Hualpén | J13: Lautaro | K13: Valdivia | L13: Hualaihué
C14: Río Hurtado | D14: La Ligua | E14: Independencia | F14: Malloa | G14: Molina | H14: Quillón | I14: Hualqui | J14: Loncoche | L14: Llanquihue
C15: Salamanca | D15: Limache | E15: Isla de Maipo | F15: Marchigüe | G15: Parral | H15: Quirihue | I15: Laja | J15: Lonquimay | L15: Los Muermos
C16: Vicuña | D16: Llaillay | E16: Lampa | F16: Mostazal | G16: Pelarco | H16: Ránquil | I16: Lebu | J16: Los Sauces | L16: Maullín
D17: Los Andes | E17: Maipú | F17: Nancagua | G17: Pelluhue | H17: San Carlos | I17: Los Álamos | J17: Lumaco | L17: Osorno
D18: Nogales | E18: María Pinto | F18: Navidad | G18: Pencahue | H18: San Fabián | I18: Los Ángeles | J18: Melipeuco | L18: Palena
D19: Olmué | E19: Melipilla | F19: Olivar | G19: Rauco | H19: San Ignacio | I19: Lota | J19: Nueva Imperial | L19: Puerto Montt
D20: Panquehue | E20: Padre Hurtado | F20: Palmilla | G20: Retiro | H20: San Nicolás | I20: Mulchén | J20: Padre Las Casas | L20: Puerto Octay
D21: Papudo | E21: Paine | F21: Paredones | G21: Río Claro | H21: Treguaco | I21: Nacimiento | J21: Perquenco | L21: Puerto Varas
D22: Petorca | E22: Peñaflor | F22: Peralillo | G22: Romeral | H22: Yungay | I22: Negrete | J22: Pitrufquén | L22: Puqueldón
D23: Puchuncaví | E23: Peñalolén | F23: Peumo | G23: Sagrada Familia | I23: Penco | J23: Pucón | L23: Purranque
D24: Putaendo | E24: Pirque | F24: Pichidegua | G24: San Clemente | I24: Quilaco | J24: Purén | L24: Puyehue
D25: Quillota | E25: Pudahuel | F25: Pichilemu | G25: San Javier | I25: Quilleco | J25: Renaico | L25: Queilén
D26: Quilpué | E26: Puente Alto | F26: Placilla | G26: San Rafael | I26: San Pedro de la Paz | J26: Saavedra | L26: Quellón
D27: Quintero | E27: Quilicura | F27: Pumanque | G27: Talca | I27: San Rosendo | J27: Temuco | L27: Quemchi
D28: Rinconada | E28: Renca | F28: Quinta de Tilcoco | G28: Teno | I28: Santa Bárbara | J28: Teodoro Schmidt | L28: Quinchao
D29: San Antonio | E29: San Bernardo | F29: Rancagua | G29: Vichuquén | I29: Santa Juana | J29: Toltén | L29: Río Negro
D30: San Esteban | E30: San Joaquín | F30: Rengo | G30: Villa Alegre | I30: Talcahuano | J30: Traiguén | L30: San Juan de la Costa
D31: San Felipe | E31: San José de Maipo | F31: Requínoa | G31: Yerbas Buenas | I31: Tirúa | J31: Victoria | L31: San Pablo
D32: Santa María | E32: San Pedro | F32: San Fernando | I32: Tomé | J32: Vilcún
D33: Santo Domingo | E33: Santiago | F33: San Vicente | I33: Tucapel | J33: Villarrica
D34: Valparaíso | E34: Talagante | F34: Santa Cruz | I34: Yumbel
D35: Villa Alemana | E35: Tiltil
D36: Viña del Mar
D37: Zapallar

Sheet Conciliación Ventas
A1: =" Conciliación de ventas: F29 (jul "&LEFT('Flujo proyectado '!$E$7,4)&" a jun "&IF('Flujo proyectado '!$E$7="","",LEFT('Flujo proyectado '!$E$7,4)+1)&") frente a venta "&'Flujo proyectado '!$E$7&" informada" -> Conciliación de ventas: F29 (jul a jun ) frente a venta informada
A2: Fuente: formularios 29 (declaración mensual de IVA y PPM) de la Carpeta Tributaria del SII. Cifras en pesos chilenos (CLP). Azul = dato del F29; negro = fórmula; verde = vínculo a otra hoja.
A4: Período (F29) | B4: Base imponible (cód. 563) | C4: Débitos facturas emitidas (cód. 502) | D4: Notas de débito emitidas (cód. 513) | E4: Notas de crédito emitidas (cód. 510) | F4: Ventas por facturas de compra recibidas (cód. 720)
A5: ="jul-"&LEFT('Flujo proyectado '!$E$7,4) -> jul-
A6: ="ago-"&LEFT('Flujo proyectado '!$E$7,4) -> ago-
A7: ="sep-"&LEFT('Flujo proyectado '!$E$7,4) -> sep-
A8: ="oct-"&LEFT('Flujo proyectado '!$E$7,4) -> oct-
A9: ="nov-"&LEFT('Flujo proyectado '!$E$7,4) -> nov-
A10: ="dic-"&LEFT('Flujo proyectado '!$E$7,4) -> dic-
A11: ="ene-"&IF('Flujo proyectado '!$E$7="","",LEFT('Flujo proyectado '!$E$7,4)+1) -> ene-
A12: ="feb-"&IF('Flujo proyectado '!$E$7="","",LEFT('Flujo proyectado '!$E$7,4)+1) -> feb-
A13: ="mar-"&IF('Flujo proyectado '!$E$7="","",LEFT('Flujo proyectado '!$E$7,4)+1) -> mar-
A14: ="abr-"&IF('Flujo proyectado '!$E$7="","",LEFT('Flujo proyectado '!$E$7,4)+1) -> abr-
A15: ="may-"&IF('Flujo proyectado '!$E$7="","",LEFT('Flujo proyectado '!$E$7,4)+1) -> may-
A16: ="jun-"&IF('Flujo proyectado '!$E$7="","",LEFT('Flujo proyectado '!$E$7,4)+1) -> jun-
A17: Total 12 meses | B17: =SUM(B5:B16) -> 0 | C17: =SUM(C5:C16) -> 0 | D17: =SUM(D5:D16) -> 0 | E17: =SUM(E5:E16) -> 0 | F17: =SUM(F5:F16) -> 0
A19: ="CONCILIACIÓN CON LA VENTA "&'Flujo proyectado '!$E$7&" INFORMADA" -> CONCILIACIÓN CON LA VENTA INFORMADA
A20: Concepto | B20: CLP | C20: USD
A21: ="Base imponible F29, jul "&LEFT('Flujo proyectado '!$E$7,4)&" a jun "&IF('Flujo proyectado '!$E$7="","",LEFT('Flujo proyectado '!$E$7,4)+1) -> Base imponible F29, jul a jun | B21: =B17 -> 0 | C21: =B21/$B$26 -> #DIV/0!
A22: ="Venta temporada "&'Flujo proyectado '!$E$7&" informada (Resultado)" -> Venta temporada informada (Resultado) | B22: ='Anexo 1 Resultado'!$G$6 -> 0 | C22: =B22/$B$26 -> #DIV/0!
A23: ='Anexo 1 Resultado'!A5 -> 0 | B23: ='Anexo 1 Resultado'!$G$5 -> 0 | C23: =B23/$B$26 -> #DIV/0!
A24: Diferencia F29 – venta informada | B24: =B21-B22 -> 0 | C24: =B24/$B$26 -> #DIV/0!
A25: Diferencia % | B25: =B24/B22 -> #DIV/0!
A26: Valor dólar usado (CLP/USD) | B26: ='Anexo 1 Resultado'!$F$3 -> 0
